Workbook
Name age_fayzz1: 'Attendance Sheet'!$FD$6:$FD$15
Name classes: 'The Black Box'!$C$2:$C$30
Name First_name1: 'Attendance Sheet'!$C$6:$C$15
Name First_name2: 'Attendance Sheet'!$C$16:$C$25
Name First_name3: 'Attendance Sheet'!$C$26:$C$35
Name First_name4: 'Attendance Sheet'!$C$36:$C$45
Name First_name5: 'Attendance Sheet'!$C$46:$C$55
Name friday_week1_fayzz1: 'Attendance Sheet'!$M$7:$N$15
Name friday_week1_fayzz2: 'Attendance Sheet'!$M$16:$N$25
Name friday_week1_fayzz3: 'Attendance Sheet'!$M$26:$N$35
Name friday_week1_fayzz4: 'Attendance Sheet'!$M$36:$N$45
Name fridayA_week1_fayzz1: 'Attendance Sheet'!$N$7:$N$15
Name fridayA_week1_fayzz2: 'Attendance Sheet'!$N$16:$N$25
Name fridayM_week1_fayzz1: 'Attendance Sheet'!$M$7:$M$15
Name fridayM_week1_fayzz2: 'Attendance Sheet'!$M$16:$M$25
Name gender_fayzz1: 'Attendance Sheet'!$D$6:$D$15
Name Last_name1: 'Attendance Sheet'!$B$6:$B$15
Name Last_name2: 'Attendance Sheet'!$B$16:$B$25
Name Last_name3: 'Attendance Sheet'!$B$26:$B$35
Name Last_name4: 'Attendance Sheet'!$B$36:$B$45
Name Last_name5: 'Attendance Sheet'!$B$46:$B$55
Name monday: 'Attendance Sheet'!$E$6:$F$15
Name monday_week1_fayzz1: 'Attendance Sheet'!$E$7:$F$15
Name monday_week1_fayzz2: 'Attendance Sheet'!$E$16:$F$25
Name monday_week1_fayzz3: 'Attendance Sheet'!$E$26:$F$35
Name monday_week1_fayzz4: 'Attendance Sheet'!$E$36:$F$45
Name monday_week1_fayzz5: 'Attendance Sheet'!$E$46:$F$55
Name mondayA_week1_fayzz1: 'Attendance Sheet'!$F$7:$F$15
Name mondayA_week1_fayzz2: 'Attendance Sheet'!$F$16:$F$25
Name mondayM_week1_fayzz1: 'Attendance Sheet'!$E$7:$E$15
Name mondayM_week1_fayzz2: 'Attendance Sheet'!$E$16:$E$25
Name No.1: 'Attendance Sheet'!$A$6:$A$15
Name No.2: 'Attendance Sheet'!$A$16:$A$25
Name No.3: 'Attendance Sheet'!$A$26:$A$35
Name No.4: 'Attendance Sheet'!$A$36:$A$45
Name NO.5: 'Attendance Sheet'!$A$46:$A$55
Name PO.1: 'The Black Box'!$D$2:$D$4
Name term: 'The Black Box'!$B$2:$B$4
Name thursday_week1_fayzz1: 'Attendance Sheet'!$K$7:$L$15
Name thursday_week1_fayzz2: 'Attendance Sheet'!$K$16:$L$25
Name thursday_week1_fayzz3: 'Attendance Sheet'!$K$26:$L$35
Name thursday_week1_fayzz4: 'Attendance Sheet'!$K$36:$L$45
Name thursday_week1_fayzz5: 'Attendance Sheet'!$K$46:$L$55
Name thursdayA_week1_fayzz1: 'Attendance Sheet'!$L$7:$L$15
Name thursdayA_week1_fayzz2: 'Attendance Sheet'!$L$16:$L$25
Name thursdayM_week1_fayzz1: 'Attendance Sheet'!$K$7:$K$15
Name thursdayM_week1_fayzz2: 'Attendance Sheet'!$K$16:$K$25
Name tuesday_week1_fayzz1: 'Attendance Sheet'!$G$7:$H$15
Name tuesday_week1_fayzz2: 'Attendance Sheet'!$G$16:$H$25
Name tuesday_week1_fayzz3: 'Attendance Sheet'!$G$26:$H$35
Name tuesday_week1_fayzz4: 'Attendance Sheet'!$G$36:$H$45
Name tuesday_week1_fayzz5: 'Attendance Sheet'!$G$46:$H$55
Name tuesdayA_week1_fayzz1: 'Attendance Sheet'!$H$7:$H$15
Name tuesdayA_week1_fayzz2: 'Attendance Sheet'!$H$16:$H$25
Name tuesdayM_week1_fayzz1: 'Attendance Sheet'!$G$7:$G$15
Name tuesdayM_week1_fayzz2: 'Attendance Sheet'!$G$16:$G$25
Name W1_monday_afternoon: 'Attendance Sheet'!$F$6:$F$15
Name W1_monday_morning: 'Attendance Sheet'!$E$6:$E$15
Name W1_tuesday_afternoon: 'Attendance Sheet'!$H$6:$H$15
Name W1_tuesday_morning: 'Attendance Sheet'!$G$6:$G$15

Sheet The Black Box
A1: Year | B1: Term | C1: Class | D1: Possible Outcome1 | E1: Total number of student | G1: For All The Dogs
A2: 2020 | B2: 1st | C2: Creche | D2: \ | E2: =SUM(COUNTIFS('Attendance Sheet'!$D6:$D105,"<>")) -> 100
A3: 2021 | B3: 2nd | C3: K.G.1 | D3: 0
A4: 2022 | B4: 3rd | C4: K.G.2 | D4: /
A5: 2023 | C5: Nursery 1
A6: 2024 | C6: Nursery 2
A7: 2025 | C7: Basic 1
A8: 2026 | C8: Basic 2
A9: 2027 | C9: Basic 3 | O9: For All the Dogs
A10: 2028 | C10: Basic 4
A11: 2029 | C11: Basic 5
A12: 2030 | C12: Basic 6
C13: J.S.S. 1A
C14: J.S.S. 1B
C15: J.S.S. 1C
C16: J.S.S. 2A
C17: J.S.S. 2B
C18: J.S.S. 2C
C19: J.S.S. 3A
C20: J.S.S. 3B
C21: J.S.S. 3C
C22: S.S.S. 1A
C23: S.S.S. 1B
C24: S.S.S. 1C
... C30: S.S.S. 3C

Sheet Student Biodata
F1: PERSONAL DATA ON STUDENTS
A2: SN | B2: Admission Number | C2: Sur(Last)name | D2: First Name | E2: Gender | F2: Date Of Birth | G2: Name of Parent/Guardian | H2: Phone number of Parent/Guardian | I2: Religion of Parent/Guardian
A3: 1 | B3: =IF(A3="","","VPS"&TEXT(A3,"000")) -> VPS001 | C3: ojeh | D3: emmanuel | E3: male | F3: 38444
A4: 2 | B4: =IF(A4="","","VPS"&TEXT(A4,"000")) -> VPS002 | C4: adeyemi | D4: desola | E4: female
A5: 3 | B5: =IF(A5="","","VPS"&TEXT(A5,"000")) -> VPS003 | C5: olu | D5: jagah | E5: male
A6: 4 | B6: =IF(A6="","","VPS"&TEXT(A6,"000")) -> VPS004 | C6: afolabi | D6: Michael | E6: male
A7: 5 | B7: =IF(A7="","","VPS"&TEXT(A7,"000")) -> VPS005 | C7: Ernest | D7: Rachael | E7: female
B8: =IF(A8="","","VPS"&TEXT(A8,"000"))
B9: =IF(A9="","","VPS"&TEXT(A9,"000"))
B10: =IF(A10="","","VPS"&TEXT(A10,"000"))
B11: =IF(A11="","","VPS"&TEXT(A11,"000"))
B12: =IF(A12="","","VPS"&TEXT(A12,"000"))
B13: =IF(A13="","","VPS"&TEXT(A13,"000"))
B14: =IF(A14="","","VPS"&TEXT(A14,"000"))
B15: =IF(A15="","","VPS"&TEXT(A15,"000"))
B16: =IF(A16="","","VPS"&TEXT(A16,"000"))
B17: =IF(A17="","","VPS"&TEXT(A17,"000"))
B18: =IF(A18="","","VPS"&TEXT(A18,"000"))
B19: =IF(A19="","","VPS"&TEXT(A19,"000"))
... B108: =IF(A108="","","VPS"&TEXT(A108,"000"))

Sheet Attendance Sheet
O1: SCHOOL REGISTER OF ATTENDANCE
I3: 1 | S3: 2 | AC3: 3 | AM3: 4 | AX3: 5 | BG3: 6 | BQ3: 7 | CA3: 8 | CK3: 9 | CU3: 10 | DE3: 11 | DO3: 12 | DY3: 13 | EI3: 14
I4: Week Ending | S4: Week Ending | AC4: Week Ending | AM4: Week Ending | AW4: Week Ending | BG4: Week Ending | BQ4: Week Ending | CA4: Week Ending | CK4: Week Ending | CU4: Week Ending | DE4: Week Ending | DO4: Week Ending | DY4: Week Ending | EI4: Week Ending | ET4: Weekly Totals | FC4: Total Attendance for the term
A5: Student No. | B5: Last(Sur)Name | C5: First Name | D5: Gender | E5: Mon | G5: Tue | I5: Wed | K5: Thu | M5: Fri | O5: Mon | Q5: Tue | S5: Wed | U5: Thu | W5: Fri | Y5: Mon | AA5: Tue | AC5: Wed | AE5: Thu | AG5: Fri | AI5: Mon | AK5: Tue | AM5: Wed | AO5: Thu | AQ5: Fri | AS5: Mon | AU5: Tue | AW5: Wed | AY5: Thu | BA5: Fri | BC5: Mon | BE5: Tue | BG5: Wed | BI5: Thu | BK5: Fri | BM5: Mon | BO5: Tue | BQ5: Wed | BS5: Thu | BU5: Fri | BW5: Mon | BY5: Tue | CA5: Wed | CC5: Thu | CE5: Fri | CG5: Mon | CI5: Tue | CK5: Wed | CM5: Thu | CO5: Fri | CQ5: Mon | CS5: Tue | CU5: Wed | CW5: Thu | CY5: Fri | DA5: Mon | DC5: Tue | DE5: Wed | DG5: Thu | DI5: Fri | DK5: Mon | DM5: Tue | DO5: Wed | DQ5: Thu | DS5: Fri | DU5: Mon | DW5: Tue | DY5: Wed | EA5: Thu | EC5: Fri | EE5: Mon | EG5: Tue | EI5: Wed | EK5: Thu | EM5: Fri | EO5: 1 | EP5: 2 | EQ5: 3 | ER5: 4 | ES5: 5 | ET5: 6 | EU5: 7 | EV5: 8 | EW5: 9 | EX5: 10 | EY5: 11 | EZ5: 12 | FA5: 13 | FB5: 14 | FD5: Age
A6: ='Student Biodata'!B3 -> VPS001 | B6: =UPPER('Student Biodata'!C3) -> OJEH | C6: =PROPER('Student Biodata'!D3) -> Emmanuel | D6: =PROPER('Student Biodata'!E3) -> Male | E6: \ | F6: / | G6: \ | H6: / | I6: \ | J6: / | K6: \ | L6: / | M6: \ | N6: / | O6: \ | P6: / | Q6: \ | R6: / | S6: \ | T6: / | U6: \ | V6: / | W6: \ | X6: / | Y6: \ | Z6: / | AA6: \ | AB6: / | AC6: \ | AD6: / | AE6: \ | AF6: / | AG6: \ | AH6: / | AI6: \ | AJ6: / | AK6: \ | AL6: / | AM6: \ | AN6: / | AO6: \ | AP6: / | AQ6: \ | AR6: / | AS6: \ | AT6: / | AU6: \ | AV6: / | AW6: \ | AX6: / | AY6: \ | AZ6: / | BA6: \ | BB6: / | BM6: \ | BN6: / | BO6: \ | BP6: / | BQ6: \ | BR6: / | BS6: \ | BT6: / | BU6: \ | BV6: / | BW6: \ | BX6: / | BY6: \ | BZ6: / | CA6: \ | CB6: / | CC6: \ | CD6: / | CE6: \ | CF6: / | CG6: \ | CH6: / | CI6: \ | CJ6: / | CK6: \ | CL6: / | CM6: \ | CN6: / | CO6: \ | CP6: / | CQ6: \ | CR6: / | CS6: \ | CT6: / | CU6: \ | CV6: / | CW6: \ | CX6: / | CY6: \ | CZ6: / | DA6: \ | DB6: / | DC6: \ | DD6: / | DE6: \ | DF6: / | DG6: \ | DH6: / | DI6: \ | DJ6: / | DK6: \ | DL6: / | DM6: \ | DN6: / | DO6: \ | DP6: / | DQ6: \ | DR6: / | DS6: \ | DT6: / | DU6: \ | DV6: / | DW6: \ | DX6: / | DY6: \ | DZ6: / | EA6: \ | EB6: / | EC6: \ | ED6: / | EE6: \ | EF6: / | EG6: \ | EH6: / | EI6: 0 | EJ6: 0 | EK6: 0 | EL6: / | EM6: \ | EN6: / | EO6: =SUM(COUNTIFS($E$6:$N$6,"\"),COUNTIFS($E$6:$N$6,"/")) -> 10 | EP6: =SUM(COUNTIFS($O$6:$X$6,"\"),COUNTIFS($O$6:$X$6,"/")) -> 10 | EQ6: =SUM(COUNTIFS($Y$6:$AH$6,"\"),COUNTIFS($Y$6:$AH$6,"/")) -> 10 | ER6: =SUM(COUNTIFS($AI$6:$AR$6,"\"),COUNTIFS($AI$6:$AR$6,"/")) -> 10 | ES6: =SUM(COUNTIFS($AS$6:$BB$6,"\"),COUNTIFS($AS$6:$BB$6,"/")) -> 10 | ET6: =SUM(COUNTIFS($BC$6:$BL$6,"\"),COUNTIFS($BC$6:$BL$6,"/")) -> 0 | EU6: =SUM(COUNTIFS($BM$6:$BV$6,"\"),COUNTIFS($BM$6:$BV$6,"/")) -> 10 | EV6: =SUM(COUNTIFS($BW$6:$CF$6,"\"),COUNTIFS($BW$6:$CF$6,"/")) -> 10 | EW6: =SUM(COUNTIFS($CG$6:$CP$6,"\"),COUNTIFS($CG$6:$CP$6,"/")) -> 10 | EX6: =SUM(COUNTIFS($CQ$6:$CZ$6,"\"),COUNTIFS($CQ$6:$CZ$6,"/")) -> 10 | EY6: =SUM(COUNTIFS($DA$6:$DJ$6,"\"),COUNTIFS($DA$6:$DJ$6,"/")) -> 10 | EZ6: =SUM(COUNTIFS($DK$6:$DT$6,"\"),COUNTIFS($DK$6:$DT$6,"/")) -> 10 | FA6: =SUM(COUNTIFS($DU$6:$ED$6,"\"),COUNTIFS($DU$6:$ED$6,"/")) -> 10 | FB6: =SUM(COUNTIFS($EE$6:EN6,"\"),COUNTIFS($EE$6:$EN$6,"/")) -> 7 | FC6: =SUM(EO6:FB6) -> 127 | FD6: =DATEDIF('Student Biodata'!F3,TODAY(),"Y") -> 20
A7: ='Student Biodata'!B4 -> VPS002 | B7: =UPPER('Student Biodata'!C4) -> ADEYEMI | C7: =PROPER('Student Biodata'!D4) -> Desola | D7: =PROPER('Student Biodata'!E4) -> Female | E7: 0 | F7: 0 | G7: \ | H7: / | I7: \ | J7: / | K7: \ | L7: / | M7: \ | N7: / | O7: \ | P7: / | Q7: \ | R7: / | S7: \ | T7: / | U7: \ | V7: / | W7: \ | X7: / | Y7: \ | Z7: / | AA7: \ | AB7: / | AC7: \ | AD7: / | AE7: \ | AF7: / | AG7: \ | AH7: / | EO7: =SUM(COUNTIFS(E7:N7,"\"),COUNTIFS(E7:N7,"/")) -> 8 | EP7: =SUM(COUNTIFS(O7:X7,"\"),COUNTIFS(O7:X7,"/")) -> 10 | EQ7: =SUM(COUNTIFS(Y7:AH7,"\"),COUNTIFS(Y7:AH7,"/")) -> 10 | ER7: =SUM(COUNTIFS(AI7:AR7,"\"),COUNTIFS(AI7:AR7,"/")) -> 0 | ES7: =SUM(COUNTIFS(AS7:BB7,"\"),COUNTIFS(AS7:BB7,"/")) -> 0 | ET7: =SUM(COUNTIFS(BC7:BL7,"\"),COUNTIFS(BC7:BL7,"/")) -> 0 | EU7: =SUM(COUNTIFS(BM7:BV7,"\"),COUNTIFS(BM7:BV7,"/")) -> 0 | EV7: =SUM(COUNTIFS(BW7:CF7,"\"),COUNTIFS(BW7:CF7,"/")) -> 0 | EW7: =SUM(COUNTIFS(CG7:CP7,"\"),COUNTIFS(CG7:CP7,"/")) -> 0 | EX7: =SUM(COUNTIFS(CQ7:CZ7,"\"),COUNTIFS(CQ7:CZ7,"/")) -> 0 | EY7: =SUM(COUNTIFS(DA7:DJ7,"\"),COUNTIFS(DA7:DJ7,"/")) -> 0 | EZ7: =SUM(COUNTIFS(DK7:DT7,"\"),COUNTIFS(DK7:DT7,"/")) -> 0 | FA7: =SUM(COUNTIFS(DU7:ED7,"\"),COUNTIFS(DU7:ED7,"/")) -> 0 | FB7: =SUM(COUNTIFS(EE7:EN7,"\"),COUNTIFS(EE7:EN7,"/")) -> 0 | FC7: =SUM(EO7:FB7) -> 28 | FD7: =DATEDIF('Student Biodata'!F5,TODAY(),"Y") -> 126
A8: ='Student Biodata'!B5 -> VPS003 | B8: =UPPER('Student Biodata'!C5) -> OLU | C8: =PROPER('Student Biodata'!D5) -> Jagah | D8: =PROPER('Student Biodata'!E5) -> Male | E8: \ | F8: / | G8: \ | EM8: \ | EO8: =SUM(COUNTIFS(E8:N8,"\"),COUNTIFS(E8:N8,"/")) -> 3 | EP8: =SUM(COUNTIFS(O8:X8,"\"),COUNTIFS(O8:X8,"/")) -> 0 | EQ8: =SUM(COUNTIFS(Y8:AH8,"\"),COUNTIFS(Y8:AH8,"/")) -> 0 | ER8: =SUM(COUNTIFS(AI8:AR8,"\"),COUNTIFS(AI8:AR8,"/")) -> 0 | ES8: =SUM(COUNTIFS(AS8:BB8,"\"),COUNTIFS(AS8:BB8,"/")) -> 0 | ET8: =SUM(COUNTIFS(BC8:BL8,"\"),COUNTIFS(BC8:BL8,"/")) -> 0 | EU8: =SUM(COUNTIFS(BM8:BV8,"\"),COUNTIFS(BM8:BV8,"/")) -> 0 | EV8: =SUM(COUNTIFS(BW8:CF8,"\"),COUNTIFS(BW8:CF8,"/")) -> 0 | EW8: =SUM(COUNTIFS(CG8:CP8,"\"),COUNTIFS(CG8:CP8,"/")) -> 0 | EX8: =SUM(COUNTIFS(CQ8:CZ8,"\"),COUNTIFS(CQ8:CZ8,"/")) -> 0 | EY8: =SUM(COUNTIFS(DA8:DJ8,"\"),COUNTIFS(DA8:DJ8,"/")) -> 0 | EZ8: =SUM(COUNTIFS(DK8:DT8,"\"),COUNTIFS(DK8:DT8,"/")) -> 0 | FA8: =SUM(COUNTIFS(DU8:ED8,"\"),COUNTIFS(DU8:ED8,"/")) -> 0 | FB8: =SUM(COUNTIFS(EE8:EN8,"\"),COUNTIFS(EE8:EN8,"/")) -> 1 | FC8: =SUM(EO8:FB8) -> 4 | FD8: =DATEDIF('Student Biodata'!F7,TODAY(),"Y") -> 126
A9: ='Student Biodata'!B6 -> VPS004 | B9: =UPPER('Student Biodata'!C6) -> AFOLABI | C9: =PROPER('Student Biodata'!D6) -> Michael | D9: =PROPER('Student Biodata'!E6) -> Male | E9: \ | F9: / | G9: \ | H9: 0 | EI9: \ | EO9: =SUM(COUNTIFS(E9:N9,"\"),COUNTIFS(E9:N9,"/")) -> 3 | EP9: =SUM(COUNTIFS(O9:X9,"\"),COUNTIFS(O9:X9,"/")) -> 0 | EQ9: =SUM(COUNTIFS(Y9:AH9,"\"),COUNTIFS(Y9:AH9,"/")) -> 0 | ER9: =SUM(COUNTIFS(AI9:AR9,"\"),COUNTIFS(AI9:AR9,"/")) -> 0 | ES9: =SUM(COUNTIFS(AS9:BB9,"\"),COUNTIFS(AS9:BB9,"/")) -> 0 | ET9: =SUM(COUNTIFS(BC9:BL9,"\"),COUNTIFS(BC9:BL9,"/")) -> 0 | EU9: =SUM(COUNTIFS(BM9:BV9,"\"),COUNTIFS(BM9:BV9,"/")) -> 0 | EV9: =SUM(COUNTIFS(BW9:CF9,"\"),COUNTIFS(BW9:CF9,"/")) -> 0 | EW9: =SUM(COUNTIFS(CG9:CP9,"\"),COUNTIFS(CG9:CP9,"/")) -> 0 | EX9: =SUM(COUNTIFS(CQ9:CZ9,"\"),COUNTIFS(CQ9:CZ9,"/")) -> 0 | EY9: =SUM(COUNTIFS(DA9:DJ9,"\"),COUNTIFS(DA9:DJ9,"/")) -> 0 | EZ9: =SUM(COUNTIFS(DK9:DT9,"\"),COUNTIFS(DK9:DT9,"/")) -> 0 | FA9: =SUM(COUNTIFS(DU9:ED9,"\"),COUNTIFS(DU9:ED9,"/")) -> 0 | FB9: =SUM(COUNTIFS(EE9:EN9,"\"),COUNTIFS(EE9:EN9,"/")) -> 1 | FC9: =SUM(EO9:FB9) -> 4 | FD9: =DATEDIF('Student Biodata'!F9,TODAY(),"Y") -> 126
A10: ='Student Biodata'!B7 -> VPS005 | B10: =UPPER('Student Biodata'!C7) -> ERNEST | C10: =PROPER('Student Biodata'!D7) -> Rachael | D10: =PROPER('Student Biodata'!E7) -> Female | EO10: =SUM(COUNTIFS(E10:N10,"\"),COUNTIFS(E10:N10,"/")) -> 0 | EP10: =SUM(COUNTIFS(O10:X10,"\"),COUNTIFS(O10:X10,"/")) -> 0 | EQ10: =SUM(COUNTIFS(Y10:AH10,"\"),COUNTIFS(Y10:AH10,"/")) -> 0 | ER10: =SUM(COUNTIFS(AI10:AR10,"\"),COUNTIFS(AI10:AR10,"/")) -> 0 | ES10: =SUM(COUNTIFS(AS10:BB10,"\"),COUNTIFS(AS10:BB10,"/")) -> 0 | ET10: =SUM(COUNTIFS(BC10:BL10,"\"),COUNTIFS(BC10:BL10,"/")) -> 0 | EU10: =SUM(COUNTIFS(BM10:BV10,"\"),COUNTIFS(BM10:BV10,"/")) -> 0 | EV10: =SUM(COUNTIFS(BW10:CF10,"\"),COUNTIFS(BW10:CF10,"/")) -> 0 | EW10: =SUM(COUNTIFS(CG10:CP10,"\"),COUNTIFS(CG10:CP10,"/")) -> 0 | EX10: =SUM(COUNTIFS(CQ10:CZ10,"\"),COUNTIFS(CQ10:CZ10,"/")) -> 0 | EY10: =SUM(COUNTIFS(DA10:DJ10,"\"),COUNTIFS(DA10:DJ10,"/")) -> 0 | EZ10: =SUM(COUNTIFS(DK10:DT10,"\"),COUNTIFS(DK10:DT10,"/")) -> 0 | FA10: =SUM(COUNTIFS(DU10:ED10,"\"),COUNTIFS(DU10:ED10,"/")) -> 0 | FB10: =SUM(COUNTIFS(EE10:EN10,"\"),COUNTIFS(EE10:EN10,"/")) -> 0 | FC10: =SUM(EO10:FB10) -> 0 | FD10: =DATEDIF('Student Biodata'!F11,TODAY(),"Y") -> 126
A11: ='Student Biodata'!B8 | B11: =UPPER('Student Biodata'!C8) | C11: =PROPER('Student Biodata'!D8) | D11: =PROPER('Student Biodata'!E8) | EM11: \ | EN11: / | EO11: =SUM(COUNTIFS(E11:N11,"\"),COUNTIFS(E11:N11,"/")) -> 0 | EP11: =SUM(COUNTIFS(O11:X11,"\"),COUNTIFS(O11:X11,"/")) -> 0 | EQ11: =SUM(COUNTIFS(Y11:AH11,"\"),COUNTIFS(Y11:AH11,"/")) -> 0 | ER11: =SUM(COUNTIFS(AI11:AR11,"\"),COUNTIFS(AI11:AR11,"/")) -> 0 | ES11: =SUM(COUNTIFS(AS11:BB11,"\"),COUNTIFS(AS11:BB11,"/")) -> 0 | ET11: =SUM(COUNTIFS(BC11:BL11,"\"),COUNTIFS(BC11:BL11,"/")) -> 0 | EU11: =SUM(COUNTIFS(BM11:BV11,"\"),COUNTIFS(BM11:BV11,"/")) -> 0 | EV11: =SUM(COUNTIFS(BW11:CF11,"\"),COUNTIFS(BW11:CF11,"/")) -> 0 | EW11: =SUM(COUNTIFS(CG11:CP11,"\"),COUNTIFS(CG11:CP11,"/")) -> 0 | EX11: =SUM(COUNTIFS(CQ11:CZ11,"\"),COUNTIFS(CQ11:CZ11,"/")) -> 0 | EY11: =SUM(COUNTIFS(DA11:DJ11,"\"),COUNTIFS(DA11:DJ11,"/")) -> 0 | EZ11: =SUM(COUNTIFS(DK11:DT11,"\"),COUNTIFS(DK11:DT11,"/")) -> 0 | FA11: =SUM(COUNTIFS(DU11:ED11,"\"),COUNTIFS(DU11:ED11,"/")) -> 0 | FB11: =SUM(COUNTIFS(EE11:EN11,"\"),COUNTIFS(EE11:EN11,"/")) -> 2 | FC11: =SUM(EO11:FB11) -> 2 | FD11: =DATEDIF('Student Biodata'!F13,TODAY(),"Y") -> 126
A12: ='Student Biodata'!B9 | B12: =UPPER('Student Biodata'!C9) | C12: =PROPER('Student Biodata'!D9) | D12: =PROPER('Student Biodata'!E9) | EO12: =SUM(COUNTIFS(E12:N12,"\"),COUNTIFS(E12:N12,"/")) -> 0 | EP12: =SUM(COUNTIFS(O12:X12,"\"),COUNTIFS(O12:X12,"/")) -> 0 | EQ12: =SUM(COUNTIFS(Y12:AH12,"\"),COUNTIFS(Y12:AH12,"/")) -> 0 | ER12: =SUM(COUNTIFS(AI12:AR12,"\"),COUNTIFS(AI12:AR12,"/")) -> 0 | ES12: =SUM(COUNTIFS(AS12:BB12,"\"),COUNTIFS(AS12:BB12,"/")) -> 0 | ET12: =SUM(COUNTIFS(BC12:BL12,"\"),COUNTIFS(BC12:BL12,"/")) -> 0 | EU12: =SUM(COUNTIFS(BM12:BV12,"\"),COUNTIFS(BM12:BV12,"/")) -> 0 | EV12: =SUM(COUNTIFS(BW12:CF12,"\"),COUNTIFS(BW12:CF12,"/")) -> 0 | EW12: =SUM(COUNTIFS(CG12:CP12,"\"),COUNTIFS(CG12:CP12,"/")) -> 0 | EX12: =SUM(COUNTIFS(CQ12:CZ12,"\"),COUNTIFS(CQ12:CZ12,"/")) -> 0 | EY12: =SUM(COUNTIFS(DA12:DJ12,"\"),COUNTIFS(DA12:DJ12,"/")) -> 0 | EZ12: =SUM(COUNTIFS(DK12:DT12,"\"),COUNTIFS(DK12:DT12,"/")) -> 0 | FA12: =SUM(COUNTIFS(DU12:ED12,"\"),COUNTIFS(DU12:ED12,"/")) -> 0 | FB12: =SUM(COUNTIFS(EE12:EN12,"\"),COUNTIFS(EE12:EN12,"/")) -> 0 | FC12: =SUM(EO12:FB12) -> 0 | FD12: =DATEDIF('Student Biodata'!F15,TODAY(),"Y") -> 126
A13: ='Student Biodata'!B10 | B13: =UPPER('Student Biodata'!C10) | C13: =PROPER('Student Biodata'!D10) | D13: =PROPER('Student Biodata'!E10) | EH13: \ | EI13: / | EO13: =SUM(COUNTIFS(E13:N13,"\"),COUNTIFS(E13:N13,"/")) -> 0 | EP13: =SUM(COUNTIFS(O13:X13,"\"),COUNTIFS(O13:X13,"/")) -> 0 | EQ13: =SUM(COUNTIFS(Y13:AH13,"\"),COUNTIFS(Y13:AH13,"/")) -> 0 | ER13: =SUM(COUNTIFS(AI13:AR13,"\"),COUNTIFS(AI13:AR13,"/")) -> 0 | ES13: =SUM(COUNTIFS(AS13:BB13,"\"),COUNTIFS(AS13:BB13,"/")) -> 0 | ET13: =SUM(COUNTIFS(BC13:BL13,"\"),COUNTIFS(BC13:BL13,"/")) -> 0 | EU13: =SUM(COUNTIFS(BM13:BV13,"\"),COUNTIFS(BM13:BV13,"/")) -> 0 | EV13: =SUM(COUNTIFS(BW13:CF13,"\"),COUNTIFS(BW13:CF13,"/")) -> 0 | EW13: =SUM(COUNTIFS(CG13:CP13,"\"),COUNTIFS(CG13:CP13,"/")) -> 0 | EX13: =SUM(COUNTIFS(CQ13:CZ13,"\"),COUNTIFS(CQ13:CZ13,"/")) -> 0 | EY13: =SUM(COUNTIFS(DA13:DJ13,"\"),COUNTIFS(DA13:DJ13,"/")) -> 0 | EZ13: =SUM(COUNTIFS(DK13:DT13,"\"),COUNTIFS(DK13:DT13,"/")) -> 0 | FA13: =SUM(COUNTIFS(DU13:ED13,"\"),COUNTIFS(DU13:ED13,"/")) -> 0 | FB13: =SUM(COUNTIFS(EE13:EN13,"\"),COUNTIFS(EE13:EN13,"/")) -> 2 | FC13: =SUM(EO13:FB13) -> 2 | FD13: =DATEDIF('Student Biodata'!F17,TODAY(),"Y") -> 126
A14: ='Student Biodata'!B11 | B14: =UPPER('Student Biodata'!C11) | C14: =PROPER('Student Biodata'!D11) | D14: =PROPER('Student Biodata'!E11) | DG14: \ | EO14: =SUM(COUNTIFS(E14:N14,"\"),COUNTIFS(E14:N14,"/")) -> 0 | EP14: =SUM(COUNTIFS(O14:X14,"\"),COUNTIFS(O14:X14,"/")) -> 0 | EQ14: =SUM(COUNTIFS(Y14:AH14,"\"),COUNTIFS(Y14:AH14,"/")) -> 0 | ER14: =SUM(COUNTIFS(AI14:AR14,"\"),COUNTIFS(AI14:AR14,"/")) -> 0 | ES14: =SUM(COUNTIFS(AS14:BB14,"\"),COUNTIFS(AS14:BB14,"/")) -> 0 | ET14: =SUM(COUNTIFS(BC14:BL14,"\"),COUNTIFS(BC14:BL14,"/")) -> 0 | EU14: =SUM(COUNTIFS(BM14:BV14,"\"),COUNTIFS(BM14:BV14,"/")) -> 0 | EV14: =SUM(COUNTIFS(BW14:CF14,"\"),COUNTIFS(BW14:CF14,"/")) -> 0 | EW14: =SUM(COUNTIFS(CG14:CP14,"\"),COUNTIFS(CG14:CP14,"/")) -> 0 | EX14: =SUM(COUNTIFS(CQ14:CZ14,"\"),COUNTIFS(CQ14:CZ14,"/")) -> 0 | EY14: =SUM(COUNTIFS(DA14:DJ14,"\"),COUNTIFS(DA14:DJ14,"/")) -> 1 | EZ14: =SUM(COUNTIFS(DK14:DT14,"\"),COUNTIFS(DK14:DT14,"/")) -> 0 | FA14: =SUM(COUNTIFS(DU14:ED14,"\"),COUNTIFS(DU14:ED14,"/")) -> 0 | FB14: =SUM(COUNTIFS(EE14:EN14,"\"),COUNTIFS(EE14:EN14,"/")) -> 0 | FC14: =SUM(EO14:FB14) -> 1 | FD14: =DATEDIF('Student Biodata'!F19,TODAY(),"Y") -> 126
A15: ='Student Biodata'!B12 | B15: =UPPER('Student Biodata'!C12) | C15: =PROPER('Student Biodata'!D12) | D15: =PROPER('Student Biodata'!E12) | EL15: 0 | EM15: \ | EN15: / | EO15: =SUM(COUNTIFS(E15:N15,"\"),COUNTIFS(E15:N15,"/")) -> 0 | EP15: =SUM(COUNTIFS(O15:X15,"\"),COUNTIFS(O15:X15,"/")) -> 0 | EQ15: =SUM(COUNTIFS(Y15:AH15,"\"),COUNTIFS(Y15:AH15,"/")) -> 0 | ER15: =SUM(COUNTIFS(AI15:AR15,"\"),COUNTIFS(AI15:AR15,"/")) -> 0 | ES15: =SUM(COUNTIFS(AS15:BB15,"\"),COUNTIFS(AS15:BB15,"/")) -> 0 | ET15: =SUM(COUNTIFS(BC15:BL15,"\"),COUNTIFS(BC15:BL15,"/")) -> 0 | EU15: =SUM(COUNTIFS(BM15:BV15,"\"),COUNTIFS(BM15:BV15,"/")) -> 0 | EV15: =SUM(COUNTIFS(BW15:CF15,"\"),COUNTIFS(BW15:CF15,"/")) -> 0 | EW15: =SUM(COUNTIFS(CG15:CP15,"\"),COUNTIFS(CG15:CP15,"/")) -> 0 | EX15: =SUM(COUNTIFS(CQ15:CZ15,"\"),COUNTIFS(CQ15:CZ15,"/")) -> 0 | EY15: =SUM(COUNTIFS(DA15:DJ15,"\"),COUNTIFS(DA15:DJ15,"/")) -> 0 | EZ15: =SUM(COUNTIFS(DK15:DT15,"\"),COUNTIFS(DK15:DT15,"/")) -> 0 | FA15: =SUM(COUNTIFS(DU15:ED15,"\"),COUNTIFS(DU15:ED15,"/")) -> 0 | FB15: =SUM(COUNTIFS(EE15:EN15,"\"),COUNTIFS(EE15:EN15,"/")) -> 2 | FC15: =SUM(EO15:FB15) -> 2 | FD15: =DATEDIF('Student Biodata'!F21,TODAY(),"Y") -> 126
A16: ='Student Biodata'!B13 | B16: =UPPER('Student Biodata'!C13) | C16: =PROPER('Student Biodata'!D13) | D16: =PROPER('Student Biodata'!E13) | EO16: =SUM(COUNTIFS(E16:N16,"\"),COUNTIFS(E16:N16,"/")) -> 0 | EP16: =SUM(COUNTIFS(O16:X16,"\"),COUNTIFS(O16:X16,"/")) -> 0 | EQ16: =SUM(COUNTIFS(Y16:AH16,"\"),COUNTIFS(Y16:AH16,"/")) -> 0 | ER16: =SUM(COUNTIFS(AI16:AR16,"\"),COUNTIFS(AI16:AR16,"/")) -> 0 | ES16: =SUM(COUNTIFS(AS16:BB16,"\"),COUNTIFS(AS16:BB16,"/")) -> 0 | ET16: =SUM(COUNTIFS(BC16:BL16,"\"),COUNTIFS(BC16:BL16,"/")) -> 0 | EU16: =SUM(COUNTIFS(BM16:BV16,"\"),COUNTIFS(BM16:BV16,"/")) -> 0 | EV16: =SUM(COUNTIFS(BW16:CF16,"\"),COUNTIFS(BW16:CF16,"/")) -> 0 | EW16: =SUM(COUNTIFS(CG16:CP16,"\"),COUNTIFS(CG16:CP16,"/")) -> 0 | EX16: =SUM(COUNTIFS(CQ16:CZ16,"\"),COUNTIFS(CQ16:CZ16,"/")) -> 0 | EY16: =SUM(COUNTIFS(DA16:DJ16,"\"),COUNTIFS(DA16:DJ16,"/")) -> 0 | EZ16: =SUM(COUNTIFS(DK16:DT16,"\"),COUNTIFS(DK16:DT16,"/")) -> 0 | FA16: =SUM(COUNTIFS(DU16:ED16,"\"),COUNTIFS(DU16:ED16,"/")) -> 0 | FB16: =SUM(COUNTIFS(EE16:EN16,"\"),COUNTIFS(EE16:EN16,"/")) -> 0 | FC16: =SUM(EO16:FB16) -> 0 | FD16: =DATEDIF('Student Biodata'!F23,TODAY(),"Y") -> 126
A17: ='Student Biodata'!B14 | B17: =UPPER('Student Biodata'!C14) | C17: =PROPER('Student Biodata'!D14) | D17: =PROPER('Student Biodata'!E14) | EO17: =SUM(COUNTIFS(E17:N17,"\"),COUNTIFS(E17:N17,"/")) -> 0 | EP17: =SUM(COUNTIFS(O17:X17,"\"),COUNTIFS(O17:X17,"/")) -> 0 | EQ17: =SUM(COUNTIFS(Y17:AH17,"\"),COUNTIFS(Y17:AH17,"/")) -> 0 | ER17: =SUM(COUNTIFS(AI17:AR17,"\"),COUNTIFS(AI17:AR17,"/")) -> 0 | ES17: =SUM(COUNTIFS(AS17:BB17,"\"),COUNTIFS(AS17:BB17,"/")) -> 0 | ET17: =SUM(COUNTIFS(BC17:BL17,"\"),COUNTIFS(BC17:BL17,"/")) -> 0 | EU17: =SUM(COUNTIFS(BM17:BV17,"\"),COUNTIFS(BM17:BV17,"/")) -> 0 | EV17: =SUM(COUNTIFS(BW17:CF17,"\"),COUNTIFS(BW17:CF17,"/")) -> 0 | EW17: =SUM(COUNTIFS(CG17:CP17,"\"),COUNTIFS(CG17:CP17,"/")) -> 0 | EX17: =SUM(COUNTIFS(CQ17:CZ17,"\"),COUNTIFS(CQ17:CZ17,"/")) -> 0 | EY17: =SUM(COUNTIFS(DA17:DJ17,"\"),COUNTIFS(DA17:DJ17,"/")) -> 0 | EZ17: =SUM(COUNTIFS(DK17:DT17,"\"),COUNTIFS(DK17:DT17,"/")) -> 0 | FA17: =SUM(COUNTIFS(DU17:ED17,"\"),COUNTIFS(DU17:ED17,"/")) -> 0 | FB17: =SUM(COUNTIFS(EE17:EN17,"\"),COUNTIFS(EE17:EN17,"/")) -> 0 | FC17: =SUM(EO17:FB17) -> 0 | FD17: =DATEDIF('Student Biodata'!F25,TODAY(),"Y") -> 126
A18: ='Student Biodata'!B15 | B18: =UPPER('Student Biodata'!C15) | C18: =PROPER('Student Biodata'!D15) | D18: =PROPER('Student Biodata'!E15) | EO18: =SUM(COUNTIFS(E18:N18,"\"),COUNTIFS(E18:N18,"/")) -> 0 | EP18: =SUM(COUNTIFS(O18:X18,"\"),COUNTIFS(O18:X18,"/")) -> 0 | EQ18: =SUM(COUNTIFS(Y18:AH18,"\"),COUNTIFS(Y18:AH18,"/")) -> 0 | ER18: =SUM(COUNTIFS(AI18:AR18,"\"),COUNTIFS(AI18:AR18,"/")) -> 0 | ES18: =SUM(COUNTIFS(AS18:BB18,"\"),COUNTIFS(AS18:BB18,"/")) -> 0 | ET18: =SUM(COUNTIFS(BC18:BL18,"\"),COUNTIFS(BC18:BL18,"/")) -> 0 | EU18: =SUM(COUNTIFS(BM18:BV18,"\"),COUNTIFS(BM18:BV18,"/")) -> 0 | EV18: =SUM(COUNTIFS(BW18:CF18,"\"),COUNTIFS(BW18:CF18,"/")) -> 0 | EW18: =SUM(COUNTIFS(CG18:CP18,"\"),COUNTIFS(CG18:CP18,"/")) -> 0 | EX18: =SUM(COUNTIFS(CQ18:CZ18,"\"),COUNTIFS(CQ18:CZ18,"/")) -> 0 | EY18: =SUM(COUNTIFS(DA18:DJ18,"\"),COUNTIFS(DA18:DJ18,"/")) -> 0 | EZ18: =SUM(COUNTIFS(DK18:DT18,"\"),COUNTIFS(DK18:DT18,"/")) -> 0 | FA18: =SUM(COUNTIFS(DU18:ED18,"\"),COUNTIFS(DU18:ED18,"/")) -> 0 | FB18: =SUM(COUNTIFS(EE18:EN18,"\"),COUNTIFS(EE18:EN18,"/")) -> 0 | FC18: =SUM(EO18:FB18) -> 0 | FD18: =DATEDIF('Student Biodata'!F27,TODAY(),"Y") -> 126
A19: ='Student Biodata'!B16 | B19: =UPPER('Student Biodata'!C16) | C19: =PROPER('Student Biodata'!D16) | D19: =PROPER('Student Biodata'!E16) | EO19: =SUM(COUNTIFS(E19:N19,"\"),COUNTIFS(E19:N19,"/")) -> 0 | EP19: =SUM(COUNTIFS(O19:X19,"\"),COUNTIFS(O19:X19,"/")) -> 0 | EQ19: =SUM(COUNTIFS(Y19:AH19,"\"),COUNTIFS(Y19:AH19,"/")) -> 0 | ER19: =SUM(COUNTIFS(AI19:AR19,"\"),COUNTIFS(AI19:AR19,"/")) -> 0 | ES19: =SUM(COUNTIFS(AS19:BB19,"\"),COUNTIFS(AS19:BB19,"/")) -> 0 | ET19: =SUM(COUNTIFS(BC19:BL19,"\"),COUNTIFS(BC19:BL19,"/")) -> 0 | EU19: =SUM(COUNTIFS(BM19:BV19,"\"),COUNTIFS(BM19:BV19,"/")) -> 0 | EV19: =SUM(COUNTIFS(BW19:CF19,"\"),COUNTIFS(BW19:CF19,"/")) -> 0 | EW19: =SUM(COUNTIFS(CG19:CP19,"\"),COUNTIFS(CG19:CP19,"/")) -> 0 | EX19: =SUM(COUNTIFS(CQ19:CZ19,"\"),COUNTIFS(CQ19:CZ19,"/")) -> 0 | EY19: =SUM(COUNTIFS(DA19:DJ19,"\"),COUNTIFS(DA19:DJ19,"/")) -> 0 | EZ19: =SUM(COUNTIFS(DK19:DT19,"\"),COUNTIFS(DK19:DT19,"/")) -> 0 | FA19: =SUM(COUNTIFS(DU19:ED19,"\"),COUNTIFS(DU19:ED19,"/")) -> 0 | FB19: =SUM(COUNTIFS(EE19:EN19,"\"),COUNTIFS(EE19:EN19,"/")) -> 0 | FC19: =SUM(EO19:FB19) -> 0 | FD19: =DATEDIF('Student Biodata'!F29,TODAY(),"Y") -> 126
A20: ='Student Biodata'!B17 | B20: =UPPER('Student Biodata'!C17) | C20: =PROPER('Student Biodata'!D17) | D20: =PROPER('Student Biodata'!E17) | EK20: \ | EL20: / | EO20: =SUM(COUNTIFS(E20:N20,"\"),COUNTIFS(E20:N20,"/")) -> 0 | EP20: =SUM(COUNTIFS(O20:X20,"\"),COUNTIFS(O20:X20,"/")) -> 0 | EQ20: =SUM(COUNTIFS(Y20:AH20,"\"),COUNTIFS(Y20:AH20,"/")) -> 0 | ER20: =SUM(COUNTIFS(AI20:AR20,"\"),COUNTIFS(AI20:AR20,"/")) -> 0 | ES20: =SUM(COUNTIFS(AS20:BB20,"\"),COUNTIFS(AS20:BB20,"/")) -> 0 | ET20: =SUM(COUNTIFS(BC20:BL20,"\"),COUNTIFS(BC20:BL20,"/")) -> 0 | EU20: =SUM(COUNTIFS(BM20:BV20,"\"),COUNTIFS(BM20:BV20,"/")) -> 0 | EV20: =SUM(COUNTIFS(BW20:CF20,"\"),COUNTIFS(BW20:CF20,"/")) -> 0 | EW20: =SUM(COUNTIFS(CG20:CP20,"\"),COUNTIFS(CG20:CP20,"/")) -> 0 | EX20: =SUM(COUNTIFS(CQ20:CZ20,"\"),COUNTIFS(CQ20:CZ20,"/")) -> 0 | EY20: =SUM(COUNTIFS(DA20:DJ20,"\"),COUNTIFS(DA20:DJ20,"/")) -> 0 | EZ20: =SUM(COUNTIFS(DK20:DT20,"\"),COUNTIFS(DK20:DT20,"/")) -> 0 | FA20: =SUM(COUNTIFS(DU20:ED20,"\"),COUNTIFS(DU20:ED20,"/")) -> 0 | FB20: =SUM(COUNTIFS(EE20:EN20,"\"),COUNTIFS(EE20:EN20,"/")) -> 2 | FC20: =SUM(EO20:FB20) -> 2 | FD20: =DATEDIF('Student Biodata'!F31,TODAY(),"Y") -> 126
A21: ='Student Biodata'!B18 | B21: =UPPER('Student Biodata'!C18) | C21: =PROPER('Student Biodata'!D18) | D21: =PROPER('Student Biodata'!E18) | EO21: =SUM(COUNTIFS(E21:N21,"\"),COUNTIFS(E21:N21,"/")) -> 0 | EP21: =SUM(COUNTIFS(O21:X21,"\"),COUNTIFS(O21:X21,"/")) -> 0 | EQ21: =SUM(COUNTIFS(Y21:AH21,"\"),COUNTIFS(Y21:AH21,"/")) -> 0 | ER21: =SUM(COUNTIFS(AI21:AR21,"\"),COUNTIFS(AI21:AR21,"/")) -> 0 | ES21: =SUM(COUNTIFS(AS21:BB21,"\"),COUNTIFS(AS21:BB21,"/")) -> 0 | ET21: =SUM(COUNTIFS(BC21:BL21,"\"),COUNTIFS(BC21:BL21,"/")) -> 0 | EU21: =SUM(COUNTIFS(BM21:BV21,"\"),COUNTIFS(BM21:BV21,"/")) -> 0 | EV21: =SUM(COUNTIFS(BW21:CF21,"\"),COUNTIFS(BW21:CF21,"/")) -> 0 | EW21: =SUM(COUNTIFS(CG21:CP21,"\"),COUNTIFS(CG21:CP21,"/")) -> 0 | EX21: =SUM(COUNTIFS(CQ21:CZ21,"\"),COUNTIFS(CQ21:CZ21,"/")) -> 0 | EY21: =SUM(COUNTIFS(DA21:DJ21,"\"),COUNTIFS(DA21:DJ21,"/")) -> 0 | EZ21: =SUM(COUNTIFS(DK21:DT21,"\"),COUNTIFS(DK21:DT21,"/")) -> 0 | FA21: =SUM(COUNTIFS(DU21:ED21,"\"),COUNTIFS(DU21:ED21,"/")) -> 0 | FB21: =SUM(COUNTIFS(EE21:EN21,"\"),COUNTIFS(EE21:EN21,"/")) -> 0 | FC21: =SUM(EO21:FB21) -> 0 | FD21: =DATEDIF('Student Biodata'!F33,TODAY(),"Y") -> 126
A22: ='Student Biodata'!B19 | B22: =UPPER('Student Biodata'!C19) | C22: =PROPER('Student Biodata'!D19) | D22: =PROPER('Student Biodata'!E19) | EO22: =SUM(COUNTIFS(E22:N22,"\"),COUNTIFS(E22:N22,"/")) -> 0 | EP22: =SUM(COUNTIFS(O22:X22,"\"),COUNTIFS(O22:X22,"/")) -> 0 | EQ22: =SUM(COUNTIFS(Y22:AH22,"\"),COUNTIFS(Y22:AH22,"/")) -> 0 | ER22: =SUM(COUNTIFS(AI22:AR22,"\"),COUNTIFS(AI22:AR22,"/")) -> 0 | ES22: =SUM(COUNTIFS(AS22:BB22,"\"),COUNTIFS(AS22:BB22,"/")) -> 0 | ET22: =SUM(COUNTIFS(BC22:BL22,"\"),COUNTIFS(BC22:BL22,"/")) -> 0 | EU22: =SUM(COUNTIFS(BM22:BV22,"\"),COUNTIFS(BM22:BV22,"/")) -> 0 | EV22: =SUM(COUNTIFS(BW22:CF22,"\"),COUNTIFS(BW22:CF22,"/")) -> 0 | EW22: =SUM(COUNTIFS(CG22:CP22,"\"),COUNTIFS(CG22:CP22,"/")) -> 0 | EX22: =SUM(COUNTIFS(CQ22:CZ22,"\"),COUNTIFS(CQ22:CZ22,"/")) -> 0 | EY22: =SUM(COUNTIFS(DA22:DJ22,"\"),COUNTIFS(DA22:DJ22,"/")) -> 0 | EZ22: =SUM(COUNTIFS(DK22:DT22,"\"),COUNTIFS(DK22:DT22,"/")) -> 0 | FA22: =SUM(COUNTIFS(DU22:ED22,"\"),COUNTIFS(DU22:ED22,"/")) -> 0 | FB22: =SUM(COUNTIFS(EE22:EN22,"\"),COUNTIFS(EE22:EN22,"/")) -> 0 | FC22: =SUM(EO22:FB22) -> 0 | FD22: =DATEDIF('Student Biodata'!F35,TODAY(),"Y") -> 126
A23: ='Student Biodata'!B20 | B23: =UPPER('Student Biodata'!C20) | C23: =PROPER('Student Biodata'!D20) | D23: =PROPER('Student Biodata'!E20) | EO23: =SUM(COUNTIFS(E23:N23,"\"),COUNTIFS(E23:N23,"/")) -> 0 | EP23: =SUM(COUNTIFS(O23:X23,"\"),COUNTIFS(O23:X23,"/")) -> 0 | EQ23: =SUM(COUNTIFS(Y23:AH23,"\"),COUNTIFS(Y23:AH23,"/")) -> 0 | ER23: =SUM(COUNTIFS(AI23:AR23,"\"),COUNTIFS(AI23:AR23,"/")) -> 0 | ES23: =SUM(COUNTIFS(AS23:BB23,"\"),COUNTIFS(AS23:BB23,"/")) -> 0 | ET23: =SUM(COUNTIFS(BC23:BL23,"\"),COUNTIFS(BC23:BL23,"/")) -> 0 | EU23: =SUM(COUNTIFS(BM23:BV23,"\"),COUNTIFS(BM23:BV23,"/")) -> 0 | EV23: =SUM(COUNTIFS(BW23:CF23,"\"),COUNTIFS(BW23:CF23,"/")) -> 0 | EW23: =SUM(COUNTIFS(CG23:CP23,"\"),COUNTIFS(CG23:CP23,"/")) -> 0 | EX23: =SUM(COUNTIFS(CQ23:CZ23,"\"),COUNTIFS(CQ23:CZ23,"/")) -> 0 | EY23: =SUM(COUNTIFS(DA23:DJ23,"\"),COUNTIFS(DA23:DJ23,"/")) -> 0 | EZ23: =SUM(COUNTIFS(DK23:DT23,"\"),COUNTIFS(DK23:DT23,"/")) -> 0 | FA23: =SUM(COUNTIFS(DU23:ED23,"\"),COUNTIFS(DU23:ED23,"/")) -> 0 | FB23: =SUM(COUNTIFS(EE23:EN23,"\"),COUNTIFS(EE23:EN23,"/")) -> 0 | FC23: =SUM(EO23:FB23) -> 0 | FD23: =DATEDIF('Student Biodata'!F37,TODAY(),"Y") -> 126
A24: ='Student Biodata'!B21 | B24: =UPPER('Student Biodata'!C21) | C24: =PROPER('Student Biodata'!D21) | D24: =PROPER('Student Biodata'!E21) | O24: \ | U24: \ | EO24: =SUM(COUNTIFS(E24:N24,"\"),COUNTIFS(E24:N24,"/")) -> 0 | EP24: =SUM(COUNTIFS(O24:X24,"\"),COUNTIFS(O24:X24,"/")) -> 2 | EQ24: =SUM(COUNTIFS(Y24:AH24,"\"),COUNTIFS(Y24:AH24,"/")) -> 0 | ER24: =SUM(COUNTIFS(AI24:AR24,"\"),COUNTIFS(AI24:AR24,"/")) -> 0 | ES24: =SUM(COUNTIFS(AS24:BB24,"\"),COUNTIFS(AS24:BB24,"/")) -> 0 | ET24: =SUM(COUNTIFS(BC24:BL24,"\"),COUNTIFS(BC24:BL24,"/")) -> 0 | EU24: =SUM(COUNTIFS(BM24:BV24,"\"),COUNTIFS(BM24:BV24,"/")) -> 0 | EV24: =SUM(COUNTIFS(BW24:CF24,"\"),COUNTIFS(BW24:CF24,"/")) -> 0 | EW24: =SUM(COUNTIFS(CG24:CP24,"\"),COUNTIFS(CG24:CP24,"/")) -> 0 | EX24: =SUM(COUNTIFS(CQ24:CZ24,"\"),COUNTIFS(CQ24:CZ24,"/")) -> 0 | EY24: =SUM(COUNTIFS(DA24:DJ24,"\"),COUNTIFS(DA24:DJ24,"/")) -> 0 | EZ24: =SUM(COUNTIFS(DK24:DT24,"\"),COUNTIFS(DK24:DT24,"/")) -> 0 | FA24: =SUM(COUNTIFS(DU24:ED24,"\"),COUNTIFS(DU24:ED24,"/")) -> 0 | FB24: =SUM(COUNTIFS(EE24:EN24,"\"),COUNTIFS(EE24:EN24,"/")) -> 0 | FC24: =SUM(EO24:FB24) -> 2 | FD24: =DATEDIF('Student Biodata'!F39,TODAY(),"Y") -> 126
A25: ='Student Biodata'!B22 | B25: =UPPER('Student Biodata'!C22) | C25: =PROPER('Student Biodata'!D22) | D25: =PROPER('Student Biodata'!E22) | EO25: =SUM(COUNTIFS(E25:N25,"\"),COUNTIFS(E25:N25,"/")) -> 0 | EP25: =SUM(COUNTIFS(O25:X25,"\"),COUNTIFS(O25:X25,"/")) -> 0 | EQ25: =SUM(COUNTIFS(Y25:AH25,"\"),COUNTIFS(Y25:AH25,"/")) -> 0 | ER25: =SUM(COUNTIFS(AI25:AR25,"\"),COUNTIFS(AI25:AR25,"/")) -> 0 | ES25: =SUM(COUNTIFS(AS25:BB25,"\"),COUNTIFS(AS25:BB25,"/")) -> 0 | ET25: =SUM(COUNTIFS(BC25:BL25,"\"),COUNTIFS(BC25:BL25,"/")) -> 0 | EU25: =SUM(COUNTIFS(BM25:BV25,"\"),COUNTIFS(BM25:BV25,"/")) -> 0 | EV25: =SUM(COUNTIFS(BW25:CF25,"\"),COUNTIFS(BW25:CF25,"/")) -> 0 | EW25: =SUM(COUNTIFS(CG25:CP25,"\"),COUNTIFS(CG25:CP25,"/")) -> 0 | EX25: =SUM(COUNTIFS(CQ25:CZ25,"\"),COUNTIFS(CQ25:CZ25,"/")) -> 0 | EY25: =SUM(COUNTIFS(DA25:DJ25,"\"),COUNTIFS(DA25:DJ25,"/")) -> 0 | EZ25: =SUM(COUNTIFS(DK25:DT25,"\"),COUNTIFS(DK25:DT25,"/")) -> 0 | FA25: =SUM(COUNTIFS(DU25:ED25,"\"),COUNTIFS(DU25:ED25,"/")) -> 0 | FB25: =SUM(COUNTIFS(EE25:EN25,"\"),COUNTIFS(EE25:EN25,"/")) -> 0 | FC25: =SUM(EO25:FB25) -> 0 | FD25: =DATEDIF('Student Biodata'!F41,TODAY(),"Y") -> 126
A26: ='Student Biodata'!B23 | B26: =UPPER('Student Biodata'!C23) | C26: =PROPER('Student Biodata'!D23) | D26: =PROPER('Student Biodata'!E23) | EO26: =SUM(COUNTIFS(E26:N26,"\"),COUNTIFS(E26:N26,"/")) -> 0 | EP26: =SUM(COUNTIFS(O26:X26,"\"),COUNTIFS(O26:X26,"/")) -> 0 | EQ26: =SUM(COUNTIFS(Y26:AH26,"\"),COUNTIFS(Y26:AH26,"/")) -> 0 | ER26: =SUM(COUNTIFS(AI26:AR26,"\"),COUNTIFS(AI26:AR26,"/")) -> 0 | ES26: =SUM(COUNTIFS(AS26:BB26,"\"),COUNTIFS(AS26:BB26,"/")) -> 0 | ET26: =SUM(COUNTIFS(BC26:BL26,"\"),COUNTIFS(BC26:BL26,"/")) -> 0 | EU26: =SUM(COUNTIFS(BM26:BV26,"\"),COUNTIFS(BM26:BV26,"/")) -> 0 | EV26: =SUM(COUNTIFS(BW26:CF26,"\"),COUNTIFS(BW26:CF26,"/")) -> 0 | EW26: =SUM(COUNTIFS(CG26:CP26,"\"),COUNTIFS(CG26:CP26,"/")) -> 0 | EX26: =SUM(COUNTIFS(CQ26:CZ26,"\"),COUNTIFS(CQ26:CZ26,"/")) -> 0 | EY26: =SUM(COUNTIFS(DA26:DJ26,"\"),COUNTIFS(DA26:DJ26,"/")) -> 0 | EZ26: =SUM(COUNTIFS(DK26:DT26,"\"),COUNTIFS(DK26:DT26,"/")) -> 0 | FA26: =SUM(COUNTIFS(DU26:ED26,"\"),COUNTIFS(DU26:ED26,"/")) -> 0 | FB26: =SUM(COUNTIFS(EE26:EN26,"\"),COUNTIFS(EE26:EN26,"/")) -> 0 | FC26: =SUM(EO26:FB26) -> 0 | FD26: =DATEDIF('Student Biodata'!F43,TODAY(),"Y") -> 126
A27: ='Student Biodata'!B24 | B27: =UPPER('Student Biodata'!C24) | C27: =PROPER('Student Biodata'!D24) | D27: =PROPER('Student Biodata'!E24) | EO27: =SUM(COUNTIFS(E27:N27,"\"),COUNTIFS(E27:N27,"/")) -> 0 | EP27: =SUM(COUNTIFS(O27:X27,"\"),COUNTIFS(O27:X27,"/")) -> 0 | EQ27: =SUM(COUNTIFS(Y27:AH27,"\"),COUNTIFS(Y27:AH27,"/")) -> 0 | ER27: =SUM(COUNTIFS(AI27:AR27,"\"),COUNTIFS(AI27:AR27,"/")) -> 0 | ES27: =SUM(COUNTIFS(AS27:BB27,"\"),COUNTIFS(AS27:BB27,"/")) -> 0 | ET27: =SUM(COUNTIFS(BC27:BL27,"\"),COUNTIFS(BC27:BL27,"/")) -> 0 | EU27: =SUM(COUNTIFS(BM27:BV27,"\"),COUNTIFS(BM27:BV27,"/")) -> 0 | EV27: =SUM(COUNTIFS(BW27:CF27,"\"),COUNTIFS(BW27:CF27,"/")) -> 0 | EW27: =SUM(COUNTIFS(CG27:CP27,"\"),COUNTIFS(CG27:CP27,"/")) -> 0 | EX27: =SUM(COUNTIFS(CQ27:CZ27,"\"),COUNTIFS(CQ27:CZ27,"/")) -> 0 | EY27: =SUM(COUNTIFS(DA27:DJ27,"\"),COUNTIFS(DA27:DJ27,"/")) -> 0 | EZ27: =SUM(COUNTIFS(DK27:DT27,"\"),COUNTIFS(DK27:DT27,"/")) -> 0 | FA27: =SUM(COUNTIFS(DU27:ED27,"\"),COUNTIFS(DU27:ED27,"/")) -> 0 | FB27: =SUM(COUNTIFS(EE27:EN27,"\"),COUNTIFS(EE27:EN27,"/")) -> 0 | FC27: =SUM(EO27:FB27) -> 0 | FD27: =DATEDIF('Student Biodata'!F45,TODAY(),"Y") -> 126
A28: ='Student Biodata'!B25 | B28: =UPPER('Student Biodata'!C25) | C28: =PROPER('Student Biodata'!D25) | D28: =PROPER('Student Biodata'!E25) | EO28: =SUM(COUNTIFS(E28:N28,"\"),COUNTIFS(E28:N28,"/")) -> 0 | EP28: =SUM(COUNTIFS(O28:X28,"\"),COUNTIFS(O28:X28,"/")) -> 0 | EQ28: =SUM(COUNTIFS(Y28:AH28,"\"),COUNTIFS(Y28:AH28,"/")) -> 0 | ER28: =SUM(COUNTIFS(AI28:AR28,"\"),COUNTIFS(AI28:AR28,"/")) -> 0 | ES28: =SUM(COUNTIFS(AS28:BB28,"\"),COUNTIFS(AS28:BB28,"/")) -> 0 | ET28: =SUM(COUNTIFS(BC28:BL28,"\"),COUNTIFS(BC28:BL28,"/")) -> 0 | EU28: =SUM(COUNTIFS(BM28:BV28,"\"),COUNTIFS(BM28:BV28,"/")) -> 0 | EV28: =SUM(COUNTIFS(BW28:CF28,"\"),COUNTIFS(BW28:CF28,"/")) -> 0 | EW28: =SUM(COUNTIFS(CG28:CP28,"\"),COUNTIFS(CG28:CP28,"/")) -> 0 | EX28: =SUM(COUNTIFS(CQ28:CZ28,"\"),COUNTIFS(CQ28:CZ28,"/")) -> 0 | EY28: =SUM(COUNTIFS(DA28:DJ28,"\"),COUNTIFS(DA28:DJ28,"/")) -> 0 | EZ28: =SUM(COUNTIFS(DK28:DT28,"\"),COUNTIFS(DK28:DT28,"/")) -> 0 | FA28: =SUM(COUNTIFS(DU28:ED28,"\"),COUNTIFS(DU28:ED28,"/")) -> 0 | FB28: =SUM(COUNTIFS(EE28:EN28,"\"),COUNTIFS(EE28:EN28,"/")) -> 0 | FC28: =SUM(EO28:FB28) -> 0 | FD28: =DATEDIF('Student Biodata'!F47,TODAY(),"Y") -> 126
A29: ='Student Biodata'!B26 | B29: =UPPER('Student Biodata'!C26) | C29: =PROPER('Student Biodata'!D26) | D29: =PROPER('Student Biodata'!E26) | BQ29: \ | EO29: =SUM(COUNTIFS(E29:N29,"\"),COUNTIFS(E29:N29,"/")) -> 0 | EP29: =SUM(COUNTIFS(O29:X29,"\"),COUNTIFS(O29:X29,"/")) -> 0 | EQ29: =SUM(COUNTIFS(Y29:AH29,"\"),COUNTIFS(Y29:AH29,"/")) -> 0 | ER29: =SUM(COUNTIFS(AI29:AR29,"\"),COUNTIFS(AI29:AR29,"/")) -> 0 | ES29: =SUM(COUNTIFS(AS29:BB29,"\"),COUNTIFS(AS29:BB29,"/")) -> 0 | ET29: =SUM(COUNTIFS(BC29:BL29,"\"),COUNTIFS(BC29:BL29,"/")) -> 0 | EU29: =SUM(COUNTIFS(BM29:BV29,"\"),COUNTIFS(BM29:BV29,"/")) -> 1 | EV29: =SUM(COUNTIFS(BW29:CF29,"\"),COUNTIFS(BW29:CF29,"/")) -> 0 | EW29: =SUM(COUNTIFS(CG29:CP29,"\"),COUNTIFS(CG29:CP29,"/")) -> 0 | EX29: =SUM(COUNTIFS(CQ29:CZ29,"\"),COUNTIFS(CQ29:CZ29,"/")) -> 0 | EY29: =SUM(COUNTIFS(DA29:DJ29,"\"),COUNTIFS(DA29:DJ29,"/")) -> 0 | EZ29: =SUM(COUNTIFS(DK29:DT29,"\"),COUNTIFS(DK29:DT29,"/")) -> 0 | FA29: =SUM(COUNTIFS(DU29:ED29,"\"),COUNTIFS(DU29:ED29,"/")) -> 0 | FB29: =SUM(COUNTIFS(EE29:EN29,"\"),COUNTIFS(EE29:EN29,"/")) -> 0 | FC29: =SUM(EO29:FB29) -> 1 | FD29: =DATEDIF('Student Biodata'!F49,TODAY(),"Y") -> 126
A30: ='Student Biodata'!B27 | B30: =UPPER('Student Biodata'!C27) | C30: =PROPER('Student Biodata'!D27) | D30: =PROPER('Student Biodata'!E27) | EO30: =SUM(COUNTIFS(E30:N30,"\"),COUNTIFS(E30:N30,"/")) -> 0 | EP30: =SUM(COUNTIFS(O30:X30,"\"),COUNTIFS(O30:X30,"/")) -> 0 | EQ30: =SUM(COUNTIFS(Y30:AH30,"\"),COUNTIFS(Y30:AH30,"/")) -> 0 | ER30: =SUM(COUNTIFS(AI30:AR30,"\"),COUNTIFS(AI30:AR30,"/")) -> 0 | ES30: =SUM(COUNTIFS(AS30:BB30,"\"),COUNTIFS(AS30:BB30,"/")) -> 0 | ET30: =SUM(COUNTIFS(BC30:BL30,"\"),COUNTIFS(BC30:BL30,"/")) -> 0 | EU30: =SUM(COUNTIFS(BM30:BV30,"\"),COUNTIFS(BM30:BV30,"/")) -> 0 | EV30: =SUM(COUNTIFS(BW30:CF30,"\"),COUNTIFS(BW30:CF30,"/")) -> 0 | EW30: =SUM(COUNTIFS(CG30:CP30,"\"),COUNTIFS(CG30:CP30,"/")) -> 0 | EX30: =SUM(COUNTIFS(CQ30:CZ30,"\"),COUNTIFS(CQ30:CZ30,"/")) -> 0 | EY30: =SUM(COUNTIFS(DA30:DJ30,"\"),COUNTIFS(DA30:DJ30,"/")) -> 0 | EZ30: =SUM(COUNTIFS(DK30:DT30,"\"),COUNTIFS(DK30:DT30,"/")) -> 0 | FA30: =SUM(COUNTIFS(DU30:ED30,"\"),COUNTIFS(DU30:ED30,"/")) -> 0 | FB30: =SUM(COUNTIFS(EE30:EN30,"\"),COUNTIFS(EE30:EN30,"/")) -> 0 | FC30: =SUM(EO30:FB30) -> 0 | FD30: =DATEDIF('Student Biodata'!F51,TODAY(),"Y") -> 126
A31: ='Student Biodata'!B28 | B31: =UPPER('Student Biodata'!C28) | C31: =PROPER('Student Biodata'!D28) | D31: =PROPER('Student Biodata'!E28) | EO31: =SUM(COUNTIFS(E31:N31,"\"),COUNTIFS(E31:N31,"/")) -> 0 | EP31: =SUM(COUNTIFS(O31:X31,"\"),COUNTIFS(O31:X31,"/")) -> 0 | EQ31: =SUM(COUNTIFS(Y31:AH31,"\"),COUNTIFS(Y31:AH31,"/")) -> 0 | ER31: =SUM(COUNTIFS(AI31:AR31,"\"),COUNTIFS(AI31:AR31,"/")) -> 0 | ES31: =SUM(COUNTIFS(AS31:BB31,"\"),COUNTIFS(AS31:BB31,"/")) -> 0 | ET31: =SUM(COUNTIFS(BC31:BL31,"\"),COUNTIFS(BC31:BL31,"/")) -> 0 | EU31: =SUM(COUNTIFS(BM31:BV31,"\"),COUNTIFS(BM31:BV31,"/")) -> 0 | EV31: =SUM(COUNTIFS(BW31:CF31,"\"),COUNTIFS(BW31:CF31,"/")) -> 0 | EW31: =SUM(COUNTIFS(CG31:CP31,"\"),COUNTIFS(CG31:CP31,"/")) -> 0 | EX31: =SUM(COUNTIFS(CQ31:CZ31,"\"),COUNTIFS(CQ31:CZ31,"/")) -> 0 | EY31: =SUM(COUNTIFS(DA31:DJ31,"\"),COUNTIFS(DA31:DJ31,"/")) -> 0 | EZ31: =SUM(COUNTIFS(DK31:DT31,"\"),COUNTIFS(DK31:DT31,"/")) -> 0 | FA31: =SUM(COUNTIFS(DU31:ED31,"\"),COUNTIFS(DU31:ED31,"/")) -> 0 | FB31: =SUM(COUNTIFS(EE31:EN31,"\"),COUNTIFS(EE31:EN31,"/")) -> 0 | FC31: =SUM(EO31:FB31) -> 0 | FD31: =DATEDIF('Student Biodata'!F52,TODAY(),"Y") -> 126
A32: ='Student Biodata'!B29 | B32: =UPPER('Student Biodata'!C29) | C32: =PROPER('Student Biodata'!D29) | D32: =PROPER('Student Biodata'!E29) | EO32: =SUM(COUNTIFS(E32:N32,"\"),COUNTIFS(E32:N32,"/")) -> 0 | EP32: =SUM(COUNTIFS(O32:X32,"\"),COUNTIFS(O32:X32,"/")) -> 0 | EQ32: =SUM(COUNTIFS(Y32:AH32,"\"),COUNTIFS(Y32:AH32,"/")) -> 0 | ER32: =SUM(COUNTIFS(AI32:AR32,"\"),COUNTIFS(AI32:AR32,"/")) -> 0 | ES32: =SUM(COUNTIFS(AS32:BB32,"\"),COUNTIFS(AS32:BB32,"/")) -> 0 | ET32: =SUM(COUNTIFS(BC32:BL32,"\"),COUNTIFS(BC32:BL32,"/")) -> 0 | EU32: =SUM(COUNTIFS(BM32:BV32,"\"),COUNTIFS(BM32:BV32,"/")) -> 0 | EV32: =SUM(COUNTIFS(BW32:CF32,"\"),COUNTIFS(BW32:CF32,"/")) -> 0 | EW32: =SUM(COUNTIFS(CG32:CP32,"\"),COUNTIFS(CG32:CP32,"/")) -> 0 | EX32: =SUM(COUNTIFS(CQ32:CZ32,"\"),COUNTIFS(CQ32:CZ32,"/")) -> 0 | EY32: =SUM(COUNTIFS(DA32:DJ32,"\"),COUNTIFS(DA32:DJ32,"/")) -> 0 | EZ32: =SUM(COUNTIFS(DK32:DT32,"\"),COUNTIFS(DK32:DT32,"/")) -> 0 | FA32: =SUM(COUNTIFS(DU32:ED32,"\"),COUNTIFS(DU32:ED32,"/")) -> 0 | FB32: =SUM(COUNTIFS(EE32:EN32,"\"),COUNTIFS(EE32:EN32,"/")) -> 0 | FC32: =SUM(EO32:FB32) -> 0 | FD32: =DATEDIF('Student Biodata'!F54,TODAY(),"Y") -> 126
A33: ='Student Biodata'!B30 | B33: =UPPER('Student Biodata'!C30) | C33: =PROPER('Student Biodata'!D30) | D33: =PROPER('Student Biodata'!E30) | EO33: =SUM(COUNTIFS(E33:N33,"\"),COUNTIFS(E33:N33,"/")) -> 0 | EP33: =SUM(COUNTIFS(O33:X33,"\"),COUNTIFS(O33:X33,"/")) -> 0 | EQ33: =SUM(COUNTIFS(Y33:AH33,"\"),COUNTIFS(Y33:AH33,"/")) -> 0 | ER33: =SUM(COUNTIFS(AI33:AR33,"\"),COUNTIFS(AI33:AR33,"/")) -> 0 | ES33: =SUM(COUNTIFS(AS33:BB33,"\"),COUNTIFS(AS33:BB33,"/")) -> 0 | ET33: =SUM(COUNTIFS(BC33:BL33,"\"),COUNTIFS(BC33:BL33,"/")) -> 0 | EU33: =SUM(COUNTIFS(BM33:BV33,"\"),COUNTIFS(BM33:BV33,"/")) -> 0 | EV33: =SUM(COUNTIFS(BW33:CF33,"\"),COUNTIFS(BW33:CF33,"/")) -> 0 | EW33: =SUM(COUNTIFS(CG33:CP33,"\"),COUNTIFS(CG33:CP33,"/")) -> 0 | EX33: =SUM(COUNTIFS(CQ33:CZ33,"\"),COUNTIFS(CQ33:CZ33,"/")) -> 0 | EY33: =SUM(COUNTIFS(DA33:DJ33,"\"),COUNTIFS(DA33:DJ33,"/")) -> 0 | EZ33: =SUM(COUNTIFS(DK33:DT33,"\"),COUNTIFS(DK33:DT33,"/")) -> 0 | FA33: =SUM(COUNTIFS(DU33:ED33,"\"),COUNTIFS(DU33:ED33,"/")) -> 0 | FB33: =SUM(COUNTIFS(EE33:EN33,"\"),COUNTIFS(EE33:EN33,"/")) -> 0 | FC33: =SUM(EO33:FB33) -> 0 | FD33: =DATEDIF('Student Biodata'!F56,TODAY(),"Y") -> 126
A34: ='Student Biodata'!B31 | B34: =UPPER('Student Biodata'!C31) | C34: =PROPER('Student Biodata'!D31) | D34: =PROPER('Student Biodata'!E31) | EO34: =SUM(COUNTIFS(E34:N34,"\"),COUNTIFS(E34:N34,"/")) -> 0 | EP34: =SUM(COUNTIFS(O34:X34,"\"),COUNTIFS(O34:X34,"/")) -> 0 | EQ34: =SUM(COUNTIFS(Y34:AH34,"\"),COUNTIFS(Y34:AH34,"/")) -> 0 | ER34: =SUM(COUNTIFS(AI34:AR34,"\"),COUNTIFS(AI34:AR34,"/")) -> 0 | ES34: =SUM(COUNTIFS(AS34:BB34,"\"),COUNTIFS(AS34:BB34,"/")) -> 0 | ET34: =SUM(COUNTIFS(BC34:BL34,"\"),COUNTIFS(BC34:BL34,"/")) -> 0 | EU34: =SUM(COUNTIFS(BM34:BV34,"\"),COUNTIFS(BM34:BV34,"/")) -> 0 | EV34: =SUM(COUNTIFS(BW34:CF34,"\"),COUNTIFS(BW34:CF34,"/")) -> 0 | EW34: =SUM(COUNTIFS(CG34:CP34,"\"),COUNTIFS(CG34:CP34,"/")) -> 0 | EX34: =SUM(COUNTIFS(CQ34:CZ34,"\"),COUNTIFS(CQ34:CZ34,"/")) -> 0 | EY34: =SUM(COUNTIFS(DA34:DJ34,"\"),COUNTIFS(DA34:DJ34,"/")) -> 0 | EZ34: =SUM(COUNTIFS(DK34:DT34,"\"),COUNTIFS(DK34:DT34,"/")) -> 0 | FA34: =SUM(COUNTIFS(DU34:ED34,"\"),COUNTIFS(DU34:ED34,"/")) -> 0 | FB34: =SUM(COUNTIFS(EE34:EN34,"\"),COUNTIFS(EE34:EN34,"/")) -> 0 | FC34: =SUM(EO34:FB34) -> 0 | FD34: =DATEDIF('Student Biodata'!F58,TODAY(),"Y") -> 126
A35: ='Student Biodata'!B32 | B35: =UPPER('Student Biodata'!C32) | C35: =PROPER('Student Biodata'!D32) | D35: =PROPER('Student Biodata'!E32) | EO35: =SUM(COUNTIFS(E35:N35,"\"),COUNTIFS(E35:N35,"/")) -> 0 | EP35: =SUM(COUNTIFS(O35:X35,"\"),COUNTIFS(O35:X35,"/")) -> 0 | EQ35: =SUM(COUNTIFS(Y35:AH35,"\"),COUNTIFS(Y35:AH35,"/")) -> 0 | ER35: =SUM(COUNTIFS(AI35:AR35,"\"),COUNTIFS(AI35:AR35,"/")) -> 0 | ES35: =SUM(COUNTIFS(AS35:BB35,"\"),COUNTIFS(AS35:BB35,"/")) -> 0 | ET35: =SUM(COUNTIFS(BC35:BL35,"\"),COUNTIFS(BC35:BL35,"/")) -> 0 | EU35: =SUM(COUNTIFS(BM35:BV35,"\"),COUNTIFS(BM35:BV35,"/")) -> 0 | EV35: =SUM(COUNTIFS(BW35:CF35,"\"),COUNTIFS(BW35:CF35,"/")) -> 0 | EW35: =SUM(COUNTIFS(CG35:CP35,"\"),COUNTIFS(CG35:CP35,"/")) -> 0 | EX35: =SUM(COUNTIFS(CQ35:CZ35,"\"),COUNTIFS(CQ35:CZ35,"/")) -> 0 | EY35: =SUM(COUNTIFS(DA35:DJ35,"\"),COUNTIFS(DA35:DJ35,"/")) -> 0 | EZ35: =SUM(COUNTIFS(DK35:DT35,"\"),COUNTIFS(DK35:DT35,"/")) -> 0 | FA35: =SUM(COUNTIFS(DU35:ED35,"\"),COUNTIFS(DU35:ED35,"/")) -> 0 | FB35: =SUM(COUNTIFS(EE35:EN35,"\"),COUNTIFS(EE35:EN35,"/")) -> 0 | FC35: =SUM(EO35:FB35) -> 0 | FD35: =DATEDIF('Student Biodata'!F60,TODAY(),"Y") -> 126
A36: ='Student Biodata'!B33 | B36: =UPPER('Student Biodata'!C33) | C36: =PROPER('Student Biodata'!D33) | D36: =PROPER('Student Biodata'!E33) | EO36: =SUM(COUNTIFS(E36:N36,"\"),COUNTIFS(E36:N36,"/")) -> 0 | EP36: =SUM(COUNTIFS(O36:X36,"\"),COUNTIFS(O36:X36,"/")) -> 0 | EQ36: =SUM(COUNTIFS(Y36:AH36,"\"),COUNTIFS(Y36:AH36,"/")) -> 0 | ER36: =SUM(COUNTIFS(AI36:AR36,"\"),COUNTIFS(AI36:AR36,"/")) -> 0 | ES36: =SUM(COUNTIFS(AS36:BB36,"\"),COUNTIFS(AS36:BB36,"/")) -> 0 | ET36: =SUM(COUNTIFS(BC36:BL36,"\"),COUNTIFS(BC36:BL36,"/")) -> 0 | EU36: =SUM(COUNTIFS(BM36:BV36,"\"),COUNTIFS(BM36:BV36,"/")) -> 0 | EV36: =SUM(COUNTIFS(BW36:CF36,"\"),COUNTIFS(BW36:CF36,"/")) -> 0 | EW36: =SUM(COUNTIFS(CG36:CP36,"\"),COUNTIFS(CG36:CP36,"/")) -> 0 | EX36: =SUM(COUNTIFS(CQ36:CZ36,"\"),COUNTIFS(CQ36:CZ36,"/")) -> 0 | EY36: =SUM(COUNTIFS(DA36:DJ36,"\"),COUNTIFS(DA36:DJ36,"/")) -> 0 | EZ36: =SUM(COUNTIFS(DK36:DT36,"\"),COUNTIFS(DK36:DT36,"/")) -> 0 | FA36: =SUM(COUNTIFS(DU36:ED36,"\"),COUNTIFS(DU36:ED36,"/")) -> 0 | FB36: =SUM(COUNTIFS(EE36:EN36,"\"),COUNTIFS(EE36:EN36,"/")) -> 0 | FC36: =SUM(EO36:FB36) -> 0 | FD36: =DATEDIF('Student Biodata'!F62,TODAY(),"Y") -> 126
A37: ='Student Biodata'!B34 | B37: =UPPER('Student Biodata'!C34) | C37: =PROPER('Student Biodata'!D34) | D37: =PROPER('Student Biodata'!E34) | EO37: =SUM(COUNTIFS(E37:N37,"\"),COUNTIFS(E37:N37,"/")) -> 0 | EP37: =SUM(COUNTIFS(O37:X37,"\"),COUNTIFS(O37:X37,"/")) -> 0 | EQ37: =SUM(COUNTIFS(Y37:AH37,"\"),COUNTIFS(Y37:AH37,"/")) -> 0 | ER37: =SUM(COUNTIFS(AI37:AR37,"\"),COUNTIFS(AI37:AR37,"/")) -> 0 | ES37: =SUM(COUNTIFS(AS37:BB37,"\"),COUNTIFS(AS37:BB37,"/")) -> 0 | ET37: =SUM(COUNTIFS(BC37:BL37,"\"),COUNTIFS(BC37:BL37,"/")) -> 0 | EU37: =SUM(COUNTIFS(BM37:BV37,"\"),COUNTIFS(BM37:BV37,"/")) -> 0 | EV37: =SUM(COUNTIFS(BW37:CF37,"\"),COUNTIFS(BW37:CF37,"/")) -> 0 | EW37: =SUM(COUNTIFS(CG37:CP37,"\"),COUNTIFS(CG37:CP37,"/")) -> 0 | EX37: =SUM(COUNTIFS(CQ37:CZ37,"\"),COUNTIFS(CQ37:CZ37,"/")) -> 0 | EY37: =SUM(COUNTIFS(DA37:DJ37,"\"),COUNTIFS(DA37:DJ37,"/")) -> 0 | EZ37: =SUM(COUNTIFS(DK37:DT37,"\"),COUNTIFS(DK37:DT37,"/")) -> 0 | FA37: =SUM(COUNTIFS(DU37:ED37,"\"),COUNTIFS(DU37:ED37,"/")) -> 0 | FB37: =SUM(COUNTIFS(EE37:EN37,"\"),COUNTIFS(EE37:EN37,"/")) -> 0 | FC37: =SUM(EO37:FB37) -> 0 | FD37: =DATEDIF('Student Biodata'!F64,TODAY(),"Y") -> 126
A38: ='Student Biodata'!B35 | B38: =UPPER('Student Biodata'!C35) | C38: =PROPER('Student Biodata'!D35) | D38: =PROPER('Student Biodata'!E35) | CF38: / | EO38: =SUM(COUNTIFS(E38:N38,"\"),COUNTIFS(E38:N38,"/")) -> 0 | EP38: =SUM(COUNTIFS(O38:X38,"\"),COUNTIFS(O38:X38,"/")) -> 0 | EQ38: =SUM(COUNTIFS(Y38:AH38,"\"),COUNTIFS(Y38:AH38,"/")) -> 0 | ER38: =SUM(COUNTIFS(AI38:AR38,"\"),COUNTIFS(AI38:AR38,"/")) -> 0 | ES38: =SUM(COUNTIFS(AS38:BB38,"\"),COUNTIFS(AS38:BB38,"/")) -> 0 | ET38: =SUM(COUNTIFS(BC38:BL38,"\"),COUNTIFS(BC38:BL38,"/")) -> 0 | EU38: =SUM(COUNTIFS(BM38:BV38,"\"),COUNTIFS(BM38:BV38,"/")) -> 0 | EV38: =SUM(COUNTIFS(BW38:CF38,"\"),COUNTIFS(BW38:CF38,"/")) -> 1 | EW38: =SUM(COUNTIFS(CG38:CP38,"\"),COUNTIFS(CG38:CP38,"/")) -> 0 | EX38: =SUM(COUNTIFS(CQ38:CZ38,"\"),COUNTIFS(CQ38:CZ38,"/")) -> 0 | EY38: =SUM(COUNTIFS(DA38:DJ38,"\"),COUNTIFS(DA38:DJ38,"/")) -> 0 | EZ38: =SUM(COUNTIFS(DK38:DT38,"\"),COUNTIFS(DK38:DT38,"/")) -> 0 | FA38: =SUM(COUNTIFS(DU38:ED38,"\"),COUNTIFS(DU38:ED38,"/")) -> 0 | FB38: =SUM(COUNTIFS(EE38:EN38,"\"),COUNTIFS(EE38:EN38,"/")) -> 0 | FC38: =SUM(EO38:FB38) -> 1 | FD38: =DATEDIF('Student Biodata'!F66,TODAY(),"Y") -> 126
A39: ='Student Biodata'!B36 | B39: =UPPER('Student Biodata'!C36) | C39: =PROPER('Student Biodata'!D36) | D39: =PROPER('Student Biodata'!E36) | EO39: =SUM(COUNTIFS(E39:N39,"\"),COUNTIFS(E39:N39,"/")) -> 0 | EP39: =SUM(COUNTIFS(O39:X39,"\"),COUNTIFS(O39:X39,"/")) -> 0 | EQ39: =SUM(COUNTIFS(Y39:AH39,"\"),COUNTIFS(Y39:AH39,"/")) -> 0 | ER39: =SUM(COUNTIFS(AI39:AR39,"\"),COUNTIFS(AI39:AR39,"/")) -> 0 | ES39: =SUM(COUNTIFS(AS39:BB39,"\"),COUNTIFS(AS39:BB39,"/")) -> 0 | ET39: =SUM(COUNTIFS(BC39:BL39,"\"),COUNTIFS(BC39:BL39,"/")) -> 0 | EU39: =SUM(COUNTIFS(BM39:BV39,"\"),COUNTIFS(BM39:BV39,"/")) -> 0 | EV39: =SUM(COUNTIFS(BW39:CF39,"\"),COUNTIFS(BW39:CF39,"/")) -> 0 | EW39: =SUM(COUNTIFS(CG39:CP39,"\"),COUNTIFS(CG39:CP39,"/")) -> 0 | EX39: =SUM(COUNTIFS(CQ39:CZ39,"\"),COUNTIFS(CQ39:CZ39,"/")) -> 0 | EY39: =SUM(COUNTIFS(DA39:DJ39,"\"),COUNTIFS(DA39:DJ39,"/")) -> 0 | EZ39: =SUM(COUNTIFS(DK39:DT39,"\"),COUNTIFS(DK39:DT39,"/")) -> 0 | FA39: =SUM(COUNTIFS(DU39:ED39,"\"),COUNTIFS(DU39:ED39,"/")) -> 0 | FB39: =SUM(COUNTIFS(EE39:EN39,"\"),COUNTIFS(EE39:EN39,"/")) -> 0 | FC39: =SUM(EO39:FB39) -> 0 | FD39: =DATEDIF('Student Biodata'!F68,TODAY(),"Y") -> 126
A40: ='Student Biodata'!B37 | B40: =UPPER('Student Biodata'!C37) | C40: =PROPER('Student Biodata'!D37) | D40: =PROPER('Student Biodata'!E37) | EO40: =SUM(COUNTIFS(E40:N40,"\"),COUNTIFS(E40:N40,"/")) -> 0 | EP40: =SUM(COUNTIFS(O40:X40,"\"),COUNTIFS(O40:X40,"/")) -> 0 | EQ40: =SUM(COUNTIFS(Y40:AH40,"\"),COUNTIFS(Y40:AH40,"/")) -> 0 | ER40: =SUM(COUNTIFS(AI40:AR40,"\"),COUNTIFS(AI40:AR40,"/")) -> 0 | ES40: =SUM(COUNTIFS(AS40:BB40,"\"),COUNTIFS(AS40:BB40,"/")) -> 0 | ET40: =SUM(COUNTIFS(BC40:BL40,"\"),COUNTIFS(BC40:BL40,"/")) -> 0 | EU40: =SUM(COUNTIFS(BM40:BV40,"\"),COUNTIFS(BM40:BV40,"/")) -> 0 | EV40: =SUM(COUNTIFS(BW40:CF40,"\"),COUNTIFS(BW40:CF40,"/")) -> 0 | EW40: =SUM(COUNTIFS(CG40:CP40,"\"),COUNTIFS(CG40:CP40,"/")) -> 0 | EX40: =SUM(COUNTIFS(CQ40:CZ40,"\"),COUNTIFS(CQ40:CZ40,"/")) -> 0 | EY40: =SUM(COUNTIFS(DA40:DJ40,"\"),COUNTIFS(DA40:DJ40,"/")) -> 0 | EZ40: =SUM(COUNTIFS(DK40:DT40,"\"),COUNTIFS(DK40:DT40,"/")) -> 0 | FA40: =SUM(COUNTIFS(DU40:ED40,"\"),COUNTIFS(DU40:ED40,"/")) -> 0 | FB40: =SUM(COUNTIFS(EE40:EN40,"\"),COUNTIFS(EE40:EN40,"/")) -> 0 | FC40: =SUM(EO40:FB40) -> 0 | FD40: =DATEDIF('Student Biodata'!F70,TODAY(),"Y") -> 126
A41: ='Student Biodata'!B38 | B41: =UPPER('Student Biodata'!C38) | C41: =PROPER('Student Biodata'!D38) | D41: =PROPER('Student Biodata'!E38) | EO41: =SUM(COUNTIFS(E41:N41,"\"),COUNTIFS(E41:N41,"/")) -> 0 | EP41: =SUM(COUNTIFS(O41:X41,"\"),COUNTIFS(O41:X41,"/")) -> 0 | EQ41: =SUM(COUNTIFS(Y41:AH41,"\"),COUNTIFS(Y41:AH41,"/")) -> 0 | ER41: =SUM(COUNTIFS(AI41:AR41,"\"),COUNTIFS(AI41:AR41,"/")) -> 0 | ES41: =SUM(COUNTIFS(AS41:BB41,"\"),COUNTIFS(AS41:BB41,"/")) -> 0 | ET41: =SUM(COUNTIFS(BC41:BL41,"\"),COUNTIFS(BC41:BL41,"/")) -> 0 | EU41: =SUM(COUNTIFS(BM41:BV41,"\"),COUNTIFS(BM41:BV41,"/")) -> 0 | EV41: =SUM(COUNTIFS(BW41:CF41,"\"),COUNTIFS(BW41:CF41,"/")) -> 0 | EW41: =SUM(COUNTIFS(CG41:CP41,"\"),COUNTIFS(CG41:CP41,"/")) -> 0 | EX41: =SUM(COUNTIFS(CQ41:CZ41,"\"),COUNTIFS(CQ41:CZ41,"/")) -> 0 | EY41: =SUM(COUNTIFS(DA41:DJ41,"\"),COUNTIFS(DA41:DJ41,"/")) -> 0 | EZ41: =SUM(COUNTIFS(DK41:DT41,"\"),COUNTIFS(DK41:DT41,"/")) -> 0 | FA41: =SUM(COUNTIFS(DU41:ED41,"\"),COUNTIFS(DU41:ED41,"/")) -> 0 | FB41: =SUM(COUNTIFS(EE41:EN41,"\"),COUNTIFS(EE41:EN41,"/")) -> 0 | FC41: =SUM(EO41:FB41) -> 0 | FD41: =DATEDIF('Student Biodata'!F72,TODAY(),"Y") -> 126
...

Sheet Summary & Evaluation
B2: Weekly Attendance Summary & Evaluation
B7: Week 1 | G7: Week 2 | L7: Week 3 | Q7: Week 4 | V7: Week 5
B9: Morning | C9: Afternoon | G9: Morning | H9: Afternoon | L9: Morning | M9: Afternoon | Q9: Morning | R9: Afternoon | V9: Morning | W9: Afternoon
B11: =SUM(COUNTIFS('Attendance Sheet'!$E:$E,"\")) -> 3 | C11: =SUM(COUNTIFS('Attendance Sheet'!$F:$F,"/")) -> 3 | G11: =SUM(COUNTIFS('Attendance Sheet'!$O:$O,"\")) -> 3 | H11: =SUM(COUNTIFS('Attendance Sheet'!P:$P,"/")) -> 2 | L11: =SUM(COUNTIFS('Attendance Sheet'!$Y:$Y,"\")) -> 2 | M11: =SUM(COUNTIFS('Attendance Sheet'!$Z:$Z,"/")) -> 2 | Q11: =SUM(COUNTIFS('Attendance Sheet'!$AI:$AI,"\")) -> 1 | R11: =SUM(COUNTIFS('Attendance Sheet'!$AJ:$AJ,"/")) -> 1 | V11: =SUM(COUNTIFS('Attendance Sheet'!$AS:$AS,"\")) -> 1 | W11: =SUM(COUNTIFS('Attendance Sheet'!$AT:$AT,"/")) -> 1
B12: =SUM(COUNTIFS('Attendance Sheet'!$G:$G,"\")) -> 4 | C12: =SUM(COUNTIFS('Attendance Sheet'!$H:$H,"/")) -> 2 | G12: =SUM(COUNTIFS('Attendance Sheet'!$Q:Q,"\")) -> 2 | H12: =SUM(COUNTIFS('Attendance Sheet'!$R:$R,"/")) -> 2 | L12: =SUM(COUNTIFS('Attendance Sheet'!$AA:$AA,"\")) -> 2 | M12: =SUM(COUNTIFS('Attendance Sheet'!$AB:$AB,"/")) -> 2 | Q12: =SUM(COUNTIFS('Attendance Sheet'!$AK:$AK,"\")) -> 1 | R12: =SUM(COUNTIFS('Attendance Sheet'!AL:$AL,"/")) -> 1 | V12: =SUM(COUNTIFS('Attendance Sheet'!$AU:$AU,"\")) -> 1 | W12: =SUM(COUNTIFS('Attendance Sheet'!$AV:$AV,"/")) -> 1
B13: =SUM(COUNTIFS('Attendance Sheet'!$I:$I,"\")) -> 2 | C13: =SUM(COUNTIFS('Attendance Sheet'!$J:$J,"/")) -> 2 | G13: =SUM(COUNTIFS('Attendance Sheet'!$S:$S,"\")) -> 2 | H13: =SUM(COUNTIFS('Attendance Sheet'!$T:$T,"/")) -> 2 | L13: =SUM(COUNTIFS('Attendance Sheet'!$AC:$AC,"\")) -> 2 | M13: =SUM(COUNTIFS('Attendance Sheet'!$AD:$AD,"/")) -> 2 | Q13: =SUM(COUNTIFS('Attendance Sheet'!$AM:$AM,"\")) -> 1 | R13: =SUM(COUNTIFS('Attendance Sheet'!$AN:$AN,"/")) -> 1 | V13: =SUM(COUNTIFS('Attendance Sheet'!$AW:$AW,"\")) -> 1 | W13: =SUM(COUNTIFS('Attendance Sheet'!$AX:$AX,"/")) -> 1
B14: =SUM(COUNTIFS('Attendance Sheet'!$K:$K,"\")) -> 2 | C14: =SUM(COUNTIFS('Attendance Sheet'!$L:$L,"/")) -> 2 | G14: =SUM(COUNTIFS('Attendance Sheet'!$U:$U,"\")) -> 3 | H14: =SUM(COUNTIFS('Attendance Sheet'!$V:$V,"/")) -> 2 | L14: =SUM(COUNTIFS('Attendance Sheet'!$AE:$AE,"\")) -> 2 | M14: =SUM(COUNTIFS('Attendance Sheet'!$AF:$AF,"/")) -> 2 | Q14: =SUM(COUNTIFS('Attendance Sheet'!$AO:$AO,"\")) -> 1 | R14: =SUM(COUNTIFS('Attendance Sheet'!$AP:$AP,"/")) -> 1 | V14: =SUM(COUNTIFS('Attendance Sheet'!$AY:$AY,"\")) -> 1 | W14: =SUM(COUNTIFS('Attendance Sheet'!$AZ:$AZ,"/")) -> 1
B15: =SUM(COUNTIFS('Attendance Sheet'!$M:$M,"\")) -> 2 | C15: =SUM(COUNTIFS('Attendance Sheet'!$N:$N,"/")) -> 2 | G15: =SUM(COUNTIFS('Attendance Sheet'!$W:$W,"\")) -> 2 | H15: =SUM(COUNTIFS('Attendance Sheet'!$X:$X,"/")) -> 2 | L15: =SUM(COUNTIFS('Attendance Sheet'!$AG:$AG,"\")) -> 2 | M15: =SUM(COUNTIFS('Attendance Sheet'!$AH:AH,"/")) -> 2 | Q15: =SUM(COUNTIFS('Attendance Sheet'!$AQ:$AQ,"\")) -> 1 | R15: =SUM(COUNTIFS('Attendance Sheet'!$AR:$AR,"/")) -> 1 | V15: =SUM(COUNTIFS('Attendance Sheet'!$BA:$BA,"\")) -> 1 | W15: =SUM(COUNTIFS('Attendance Sheet'!$BB:$BB,"/")) -> 1
B16: =SUM($B$11:$B$15) -> 13 | C16: =SUM($C$11:$C$15) -> 11 | G16: =SUM($G$11:$G$15) -> 12 | H16: =SUM($H$11:$H$15) -> 10 | L16: =SUM($L$11:$L$15) -> 10 | M16: =SUM($M$11:$M$15) -> 10 | Q16: =SUM($Q$11:$Q$15) -> 5 | R16: =SUM($R$11:$R$15) -> 5 | V16: =SUM($V$11:$V$15) -> 5 | W16: =SUM($W$11:$W$15) -> 5
B17: =(((B16+C16)/'The Black Box'!E2)*10) -> 2.4 | G17: =(((G16+H16)/'The Black Box'!E2)*10) -> 2.2 | L17: =(((L16+M16)/'The Black Box'!E2)*10) -> 2 | Q17: =(((Q16+R16)/'The Black Box'!E2)*10) -> 1 | V17: =(((V16+W16)/'The Black Box'!E2)*10) -> 1
B21: Week 6 | G21: Week 7 | L21: Week 8 | Q21: Week 9 | V21: Week 10
B23: Morning | C23: Afternoon | G23: Morning | H23: Afternoon | L23: Morning | M23: Afternoon | Q23: Morning | R23: Afternoon | V23: Morning | W23: Afternoon
B25: =SUM(COUNTIFS('Attendance Sheet'!$BC:$BC,"\")) -> 0 | C25: =SUM(COUNTIFS('Attendance Sheet'!$BD:$BD,"/")) -> 0 | G25: =SUM(COUNTIFS('Attendance Sheet'!$BM:BM,"\")) -> 1 | H25: =SUM(COUNTIFS('Attendance Sheet'!$BN:$BN,"/")) -> 1 | L25: =SUM(COUNTIFS('Attendance Sheet'!$BW:$BW,"\")) -> 1 | M25: =SUM(COUNTIFS('Attendance Sheet'!$BX:$BX,"/")) -> 1 | Q25: =SUM(COUNTIFS('Attendance Sheet'!$CG:$CG,"\")) -> 1 | R25: =SUM(COUNTIFS('Attendance Sheet'!$CH:$CH,"/")) -> 1 | V25: =SUM(COUNTIFS('Attendance Sheet'!$CQ:$CQ,"\")) -> 1 | W25: =SUM(COUNTIFS('Attendance Sheet'!$CR:$CR,"/")) -> 1
B26: =SUM(COUNTIFS('Attendance Sheet'!$BE:$BE,"\")) -> 0 | C26: =SUM(COUNTIFS('Attendance Sheet'!$BF:$BF,"/")) -> 0 | G26: =SUM(COUNTIFS('Attendance Sheet'!$BO:$BO,"\")) -> 1 | H26: =SUM(COUNTIFS('Attendance Sheet'!$BP:$BP,"/")) -> 1 | L26: =SUM(COUNTIFS('Attendance Sheet'!$BY:$BY,"\")) -> 1 | M26: =SUM(COUNTIFS('Attendance Sheet'!$BZ:$BZ,"/")) -> 1 | Q26: =SUM(COUNTIFS('Attendance Sheet'!$CI:$CI,"\")) -> 1 | R26: =SUM(COUNTIFS('Attendance Sheet'!$CJ:$CJ,"/")) -> 1 | V26: =SUM(COUNTIFS('Attendance Sheet'!$CS:$CS,"\")) -> 2 | W26: =SUM(COUNTIFS('Attendance Sheet'!$CT:$CT,"/")) -> 1
B27: =SUM(COUNTIFS('Attendance Sheet'!$BG:$BG,"\")) -> 0 | C27: =SUM(COUNTIFS('Attendance Sheet'!$BH:$BH,"/")) -> 0 | G27: =SUM(COUNTIFS('Attendance Sheet'!$BQ:$BQ,"\")) -> 2 | H27: =SUM(COUNTIFS('Attendance Sheet'!$BR:$BR,"/")) -> 1 | L27: =SUM(COUNTIFS('Attendance Sheet'!$CA:$CA,"\")) -> 1 | M27: =SUM(COUNTIFS('Attendance Sheet'!$CB:$CB,"/")) -> 1 | Q27: =SUM(COUNTIFS('Attendance Sheet'!$CK:$CK,"\")) -> 1 | R27: =SUM(COUNTIFS('Attendance Sheet'!$CL:$CL,"/")) -> 1 | V27: =SUM(COUNTIFS('Attendance Sheet'!$CU:$CU,"\")) -> 1 | W27: =SUM(COUNTIFS('Attendance Sheet'!$CV:$CV,"/")) -> 1
B28: =SUM(COUNTIFS('Attendance Sheet'!$BI:$BI,"\")) -> 0 | C28: =SUM(COUNTIFS('Attendance Sheet'!$BJ:$BJ,"/")) -> 0 | G28: =SUM(COUNTIFS('Attendance Sheet'!$BS:$BS,"\")) -> 1 | H28: =SUM(COUNTIFS('Attendance Sheet'!$BT:$BT,"/")) -> 1 | L28: =SUM(COUNTIFS('Attendance Sheet'!$CC:$CC,"\")) -> 1 | M28: =SUM(COUNTIFS('Attendance Sheet'!$CD:$CD,"/")) -> 1 | Q28: =SUM(COUNTIFS('Attendance Sheet'!$CM:$CM,"\")) -> 1 | R28: =SUM(COUNTIFS('Attendance Sheet'!$CN:$CN,"/")) -> 1 | V28: =SUM(COUNTIFS('Attendance Sheet'!$CW:$CW,"\")) -> 1 | W28: =SUM(COUNTIFS('Attendance Sheet'!$CX:$CX,"/")) -> 1
B29: =SUM(COUNTIFS('Attendance Sheet'!$BK:$BK,"\")) -> 0 | C29: =SUM(COUNTIFS('Attendance Sheet'!$BL:$BL,"/")) -> 0 | G29: =SUM(COUNTIFS('Attendance Sheet'!$BU:$BU,"\")) -> 1 | H29: =SUM(COUNTIFS('Attendance Sheet'!$BV:$BV,"/")) -> 1 | L29: =SUM(COUNTIFS('Attendance Sheet'!$CE:$CE,"\")) -> 1 | M29: =SUM(COUNTIFS('Attendance Sheet'!$CF:$CF,"/")) -> 2 | Q29: =SUM(COUNTIFS('Attendance Sheet'!$CO:$CO,"\")) -> 1 | R29: =SUM(COUNTIFS('Attendance Sheet'!$CP:$CP,"/")) -> 1 | V29: =SUM(COUNTIFS('Attendance Sheet'!$CY:$CY,"\")) -> 1 | W29: =SUM(COUNTIFS('Attendance Sheet'!$CZ:$CZ,"/")) -> 1
B30: =SUM($B$25:$B$29) -> 0 | C30: =SUM($C$25:$C$29) -> 0 | G30: =SUM($G$25:$G$29) -> 6 | H30: =SUM($H$25:$H$29) -> 5 | L30: =SUM($L$25:$L$29) -> 5 | M30: =SUM($M$25:$M$29) -> 6 | Q30: =SUM($Q$25:$Q$29) -> 5 | R30: =SUM($R$25:$R$29) -> 5 | V30: =SUM($V$25:$V$29) -> 6 | W30: =SUM($W$25:$W$29) -> 5
B31: =(((B30+C30)/'The Black Box'!$E$2)*10) -> 0 | G31: =(((G30+H30)/'The Black Box'!E2)*10) -> 1.1 | L31: =(((L30+M30)/'The Black Box'!E2)*10) -> 1.1 | Q31: =(((Q30+R30)/'The Black Box'!E2)*10) -> 1 | V31: =(((V30+W30)/'The Black Box'!E2)*10) -> 1.1
B35: Week 11 | G35: Week 12 | Q35: Week 13 | V35: Week 14
B37: Morning | C37: Afternoon | G37: Morning | H37: Afternoon | Q37: Morning | R37: Afternoon | V37: Morning | W37: Afternoon
B39: =SUM(COUNTIFS('Attendance Sheet'!$DA:$DA,"\")) -> 1 | C39: =SUM(COUNTIFS('Attendance Sheet'!$DB:$DB,"/")) -> 1 | G39: =SUM(COUNTIFS('Attendance Sheet'!$DK:$DK,"\")) -> 1 | H39: =SUM(COUNTIFS('Attendance Sheet'!$DL:$DL,"/")) -> 1 | L39: Gender | Q39: =SUM(COUNTIFS('Attendance Sheet'!$DU:$DU,"\")) -> 1 | R39: =SUM(COUNTIFS('Attendance Sheet'!$DV:$DV,"/")) -> 1 | V39: =SUM(COUNTIFS('Attendance Sheet'!$EE:$EE,"\")) -> 1 | W39: =SUM(COUNTIFS('Attendance Sheet'!$EF:$EF,"/")) -> 1
B40: =SUM(COUNTIFS('Attendance Sheet'!$DC:$DC,"\")) -> 1 | C40: =SUM(COUNTIFS('Attendance Sheet'!$DD:DD,"/")) -> 1 | G40: =SUM(COUNTIFS('Attendance Sheet'!$DM:$DM,"\")) -> 1 | H40: =SUM(COUNTIFS('Attendance Sheet'!$DN:$DN,"/")) -> 1 | Q40: =SUM(COUNTIFS('Attendance Sheet'!$DW:$DW,"\")) -> 1 | R40: =SUM(COUNTIFS('Attendance Sheet'!$DX:$DX,"/")) -> 1 | V40: =SUM(COUNTIFS('Attendance Sheet'!$EG:$EG,"\")) -> 1 | W40: =SUM(COUNTIFS('Attendance Sheet'!$EH:$EH,"/")) -> 1
B41: =SUM(COUNTIFS('Attendance Sheet'!$DE:$DE,"\")) -> 1 | C41: =SUM(COUNTIFS('Attendance Sheet'!$DF:$DF,"/")) -> 1 | G41: =SUM(COUNTIFS('Attendance Sheet'!$DO:$DO,"\")) -> 1 | H41: =SUM(COUNTIFS('Attendance Sheet'!$DP:$DP,"/")) -> 1 | L41: Boys | M41: Girls | Q41: =SUM(COUNTIFS('Attendance Sheet'!$DY:$DY,"\")) -> 1 | R41: =SUM(COUNTIFS('Attendance Sheet'!$DZ:$DZ,"/")) -> 1 | V41: =SUM(COUNTIFS('Attendance Sheet'!$EI:$EI,"\")) -> 1 | W41: =SUM(COUNTIFS('Attendance Sheet'!$EJ:$EJ,"/")) -> 0
B42: =SUM(COUNTIFS('Attendance Sheet'!$DG:$DG,"\")) -> 2 | C42: =SUM(COUNTIFS('Attendance Sheet'!$DH:$DH,"/")) -> 1 | G42: =SUM(COUNTIFS('Attendance Sheet'!$DQ:$DQ,"\")) -> 1 | H42: =SUM(COUNTIFS('Attendance Sheet'!$DR:$DR,"/")) -> 1 | Q42: =SUM(COUNTIFS('Attendance Sheet'!$EA:$EA,"\")) -> 1 | R42: =SUM(COUNTIFS('Attendance Sheet'!$EB:$EB,"/")) -> 1 | V42: =SUM(COUNTIFS('Attendance Sheet'!$EK:$EK,"\")) -> 1 | W42: =SUM(COUNTIFS('Attendance Sheet'!$EL:$EL,"/")) -> 2
